Workbook
Name critCategory: Dash_Calc!$H$7
Name critRegion: Dash_Calc!$H$5
Name dEnd: Dash_Calc!$H$10
Name dStart: Dash_Calc!$H$9
Name lstCategory: Dash_Calc!$B$5:$B$13
Name lstMonth: Dash_Calc!$C$5:$C$17
Name lstRegion: Dash_Calc!$A$5:$A$9
Name lstScenario: Dash_Calc!$E$5:$E$8
Name selCategory: Dashboard!$G$6
Name selMonth: Dashboard!$K$6
Name selRegion: Dashboard!$C$6
Name selScenario: Dashboard!$O$6

Sheet README
A1: CareTech Commercial Analytics & Financial Modelling Capstone (v2)
A2: Synthetic data only. No service-user, employee or supplier personal data. Built for the Junior Data Analyst (Commercial) role.
A4: Business problem
A5: A growing Commercial team receives procurement, fleet, workforce, agency and finance extracts from separate systems. The extracts disagree on naming, carry duplicates and gaps, and are reported by hand. The team needs one trusted view of spend, a savings tracker it can defend, and a 2026 model that shows what pay, agency and sourcing decisions do to EBITDA.
A7: Workflow
A8: Raw CSV extracts -> VBA consolidation -> Excel Tables -> formula cleansing & DQ flags -> reconciliation -> analysis -> driver-based model -> savings tracker -> interactive dashboard -> VBA refresh & PDF report pack
A10: Sheet guide (click to open)
A11: Sheet | B11: Layer | C11: What it shows | D11: JD requirement evidenced
A12: Dashboard | B12: Presentation | C12: Interactive executive view: 4 selectors, 15 KPI cards, 4 live insight sentences, 8 charts. | D12: Recurring commercial reports; explaining findings to non-analysts
A13: Financial_Model | B13: Model | C13: Driver-based 2026 forecast, 4 scenarios, EBITDA bridge, monthly phasing, budget comparison, two sensitivity grids. | D13: Cost models and scenario analysis
A14: Savings_Tracker | B14: Model | C14: Category targets vs realised YTD, run-rate forecast, RAG status, cross-check to the model. | D14: Savings trackers
A15: Site_Performance | B15: Analysis | C15: Budget vs actual Opex and EBITDA margin by site with RAG and ranking. | D15: Finance data; variance analysis
A16: Ops_Analysis | B16: Analysis | C16: Fleet cost per mile, overtime and absence, agency rates and share of staff cost. | D16: Fleet, workforce and agency data
A17: Supplier_Analysis | B17: Analysis | C17: Supplier spend, rank, Pareto concentration and contract compliance. | D17: Supplier spend analysis
A18: Pivot_Analysis | B18: Analysis | C18: Formula cross-tabs by category, region and month. | D18: Lookups, pivots and formulas
A19: Actual_Pivot | B19: Analysis | C19: Genuine PivotTable on the cleaned table, used to validate the formulas. | D19: PivotTables
A20: Data_Quality | B20: Control | C20: Exception counts, treatment rules, reconciliations with PASS/FAIL, live exception log. | D20: Cleanse, validate, quality-assure
A21: Cleaned_Procurement | B21: Transform | C21: Formula-cleaned procurement layer: trimmed, standardised, enriched and flagged. | D21: Consistency across disparate systems
A22: Dash_Calc | B22: Engine | C22: Filtered measures and chart series behind the Dashboard. | D22: Maintainable, auditable build
... A26: Methodology | B26: Docs | C26: Assumptions, GDPR approach, limitations. | D26: GDPR-first approach
A28: Colour convention
A29: Blue text on yellow = input you can change
A30: Green text = link to another sheet
A31: Black text = calculation (do not overwrite)
A33: Five-minute demo
A34: 1. Dashboard: set Region = Wales, Month = Oct-2025. Every card, chart and sentence updates.
A35: 2. Switch scenario to Conservative: 2026 EBITDA, the bridge and the scenario chart move together.
A36: 3. Data_Quality: show the flagged exceptions and the PASS reconciliations to the finance ledger.
A37: 4. Financial_Model: walk the bridge and the sensitivity grids (payroll matters more than procurement).
A38: 5. Alt+F8 -> ExportRegionalReportPack: one PDF per region in a few seconds.

Sheet Dashboard
B2: COMMERCIAL ANALYTICS | EXECUTIVE DASHBOARD
B3: ="2025 actuals | Region: "&Dash_Calc!$H$47&" | Category: "&selCategory&" | Period: "&Dash_Calc!$H$48&" | 2026 scenario: "&selScenario -> 2025 actuals | Region: all regions | Category: All | Period: FY 2025 | 2026 scenario: Base
B4: Last refreshed: run RefreshCommercialModel (Alt+F8) to stamp this line.
B6: Region | C6: All | F6: Category | G6: All | J6: Month | K6: All | N6: 2026 scenario | O6: Base
B7: Pick from the yellow drop-downs. Region, category and month filter the actuals; the scenario drives the 2026 model. Category affects procurement cards and the supplier chart only.
B9: FINANCE (region + month filter)
B10: Revenue | E10: Actual Opex | H10: EBITDA | K10: EBITDA margin | N10: Opex vs budget
B11: =Dash_Calc!$H$13 -> 86476517 | E11: =Dash_Calc!$H$14 -> 60352965 | H11: =Dash_Calc!$H$16 -> 26123553 | K11: =Dash_Calc!$H$17 -> 0.3020884 | N11: =Dash_Calc!$H$18 -> 48856.977
B12: ="Share of group: "&TEXT(IFERROR(Dash_Calc!$H$13/Dash_Calc!$H$22,0),"0%") -> Share of group: 100% | E12: ="Budget: "&TEXT(Dash_Calc!$H$15/1000000,"£0.0")&"m" -> Budget: £60.4m | H12: ="Payroll = "&TEXT(IFERROR(Dash_Calc!$H$20/Dash_Calc!$H$13,0),"0%")&" of revenue" -> Payroll = 44% of revenue | K12: ="Group 2025: "&TEXT(Dash_Calc!$H$46,"0.0%") -> Group 2025: 30.2% | N12: =IF(Dash_Calc!$H$18>=0,"Favourable ","Adverse ")&TEXT(Dash_Calc!$H$19,"+0.0%;-0.0%") -> Favourable +0.1%
B13: PROCUREMENT (region + category + month filter)
B14: Procurement spend | E14: Savings potential | H14: Off-contract share | K14: Average invoice | N14: Data-quality exceptions
B15: =Dash_Calc!$H$23 -> 13922682 | E15: =Dash_Calc!$H$24 -> 782438.95 | H15: =Dash_Calc!$H$26 -> 0.82410798 | K15: =Dash_Calc!$H$29 -> 7734.8232 | N15: =Dash_Calc!$H$28 -> 6
B16: =TEXT(Dash_Calc!$H$27,"#,##0")&" invoices" -> 1,800 invoices | E16: =TEXT(IFERROR(Dash_Calc!$H$24/Dash_Calc!$H$23,0),"0.0%")&" of spend at target rates" -> 5.6% of spend at target rates | H16: =TEXT(Dash_Calc!$H$25/1000000,"£0.00")&"m not under contract" -> £11.47m not under contract | K16: ="Across "&TEXT(Dash_Calc!$H$27,"#,##0")&" invoices" -> Across 1,800 invoices | N16: ="Logged on Data_Quality, none deleted" -> Logged on Data_Quality, none deleted
B17: OPERATIONS (region + month) & 2026 MODEL (group, scenario)
B18: Fleet cost per mile | E18: Agency % of staff cost | H18: Overtime % of payroll | K18: 2026 EBITDA | N18: 2026 EBITDA margin
B19: =Dash_Calc!$H$33 -> 0.72741135 | E19: =Dash_Calc!$H$38 -> 0.033981885 | H19: =Dash_Calc!$H$36 -> 0.029296458 | K19: =Dash_Calc!$H$40 -> 28098167 | N19: =Dash_Calc!$H$41 -> 0.31545875
B20: =TEXT(Dash_Calc!$H$31,"#,##0")&" miles" -> 1,212,529 miles | E20: =TEXT(Dash_Calc!$H$37/1000,"£#,##0")&"k agency spend" -> £1,341k agency spend | H20: =TEXT(Dash_Calc!$H$35/1000,"£#,##0")&"k overtime" -> £1,117k overtime | K20: =IF(Dash_Calc!$H$43>=0,"+","-")&TEXT(ABS(Dash_Calc!$H$43)/1000000,"£0.0")&"m vs 2025" -> +£2.0m vs 2025 | N20: =selScenario&" scenario" -> Base scenario
B22: WHAT THE NUMBERS SAY
B23: =Dash_Calc!$H$51 -> Largest spend category in all regions, FY 2025: Agency Labour at £3,193,367 (23% of procurement spend).
B24: =Dash_Calc!$H$52 -> Top supplier for this selection is NurseLink at £1,161,388; 82% of selected spend is off-contract (£11,473,793). Category targets applied to this spend are worth £782,439.
B25: =Dash_Calc!$H$53 -> Opex for all regions, FY 2025 is £48,857 under budget (+0.1%); EBITDA margin 30.2% against a group 2025 margin of 30.2%.
B26: =Dash_Calc!$H$54 -> 2026 Base scenario: EBITDA £28.1m (31.5% margin), up £2.0m on 2025. The savings tracker forecasts 81% of the category target.
B96: Charts read from Dash_Calc, so they redraw whenever a selector changes. Source logic: Financial_Model, Savings_Tracker, Cleaned_Procurement, raw tables.

Sheet Financial_Model
A1: 2026 Driver-Based Financial Model
A2: Blue = input, green = link to another sheet, black = calculation. Scenario is chosen on the Dashboard control panel.
A3: Selected scenario | B3: =selScenario -> Base
A5: Driver | B5: Conservative | C5: Base | D5: Aggressive | E5: Custom | F5: Selected | H5: Savings plan cross-check
A6: Revenue growth | B6: 0.01 | C6: 0.03 | D6: 0.05 | E6: 0.03 | F6: =CHOOSE(MATCH($B$3,$B$5:$E$5,0),B6,C6,D6,E6) -> 0.03 | H6: Top-down: procurement saving in selected scenario | I6: =-D17 -> 556680.77
A7: Procurement savings | B7: 0.02 | C7: 0.04 | D7: 0.07 | E7: 0.04 | F7: =CHOOSE(MATCH($B$3,$B$5:$E$5,0),B7,C7,D7,E7) -> 0.04 | H7: Bottom-up: category targets (Savings_Tracker) | I7: =Savings_Tracker!E15 -> 782438.95
A8: Agency rate inflation | B8: 0.06 | C8: 0.05 | D8: 0.03 | E8: 0.05 | F8: =CHOOSE(MATCH($B$3,$B$5:$E$5,0),B8,C8,D8,E8) -> 0.05 | H8: Delivery: full-year forecast (Savings_Tracker) | I8: =Savings_Tracker!G15 -> 631350
A9: Fleet efficiency | B9: 0.01 | C9: 0.03 | D9: 0.05 | E9: 0.03 | F9: =CHOOSE(MATCH($B$3,$B$5:$E$5,0),B9,C9,D9,E9) -> 0.03 | H9: Forecast delivery minus model assumption | I9: =I8-I6 -> 74669.226
A10: Payroll inflation | B10: 0.035 | C10: 0.025 | D10: 0.02 | E10: 0.025 | F10: =CHOOSE(MATCH($B$3,$B$5:$E$5,0),B10,C10,D10,E10) -> 0.025 | H10: =IF(I9>=0,"Savings delivery supports the "&$B$3&" assumption.","Model assumes "&TEXT(-I9,"£#,##0")&" more procurement saving than the tracker is forecasting: treat "&$B$3&" as a stretch.") -> Savings delivery supports the Base assumption.
A11: Other Opex inflation | B11: 0.04 | C11: 0.03 | D11: 0.02 | E11: 0.03 | F11: =CHOOSE(MATCH($B$3,$B$5:$E$5,0),B11,C11,D11,E11) -> 0.03
A13: 2026 budget uplift on 2025 budget | B13: 0.03
A15: Metric | B15: 2025 Actual | C15: 2026 Forecast | D15: Change | E15: % Change | F15: Driver applied
A16: Revenue | B16: =SUM(Finance_Raw!E:E) -> 86476517 | C16: =B16*(1+$F$6) -> 89070813 | D16: =C16-B16 -> 2594295.5 | E16: =IFERROR(D16/B16,0) -> 0.03 | F16: x (1 + revenue growth)
A17: Procurement | B17: =SUM(Finance_Raw!G:G) -> 13917019 | C17: =B17*(1-$F$7) -> 13360339 | D17: =C17-B17 -> -556680.77 | E17: =IFERROR(D17/B17,0) -> -0.04 | F17: x (1 - procurement savings)
A18: Agency | B18: =SUM(Finance_Raw!I:I) -> 1341086 | C18: =B18*(1+$F$8) -> 1408140.3 | D18: =C18-B18 -> 67054.3 | E18: =IFERROR(D18/B18,0) -> 0.05 | F18: x (1 + agency rate inflation)
A19: Fleet | B19: =SUM(Finance_Raw!H:H) -> 882007.36 | C19: =B19*(1-$F$9) -> 855547.14 | D19: =C19-B19 -> -26460.221 | E19: =IFERROR(D19/B19,0) -> -0.03 | F19: x (1 - fleet efficiency)
A20: Payroll | B20: =SUM(Finance_Raw!F:F) -> 38123646 | C20: =B20*(1+$F$10) -> 39076737 | D20: =C20-B20 -> 953091.15 | E20: =IFERROR(D20/B20,0) -> 0.025 | F20: x (1 + payroll inflation)
A21: Other Opex | B21: =SUM(Finance_Raw!J:J) -> 6089205.9 | C21: =B21*(1+$F$11) -> 6271882.1 | D21: =C21-B21 -> 182676.18 | E21: =IFERROR(D21/B21,0) -> 0.03 | F21: x (1 + other Opex inflation)
A22: Total Opex | B22: =SUM(B17:B21) -> 60352965 | C22: =SUM(C17:C21) -> 60972645 | D22: =C22-B22 -> 619680.64 | E22: =IFERROR(D22/B22,0) -> 0.010267609
A23: EBITDA | B23: =B16-B22 -> 26123553 | C23: =C16-C22 -> 28098167 | D23: =C23-B23 -> 1974614.9 | E23: =IFERROR(D23/B23,0) -> 0.075587533 | F23: =IF(ROUND(C23-INDEX($B$36:$E$36,MATCH($B$3,$B$28:$E$28,0)),0)=0,"Check: PASS","Check: FAIL") -> Check: PASS
A24: EBITDA margin | B24: =IFERROR(B23/B16,0) -> 0.3020884 | C24: =IFERROR(C23/C16,0) -> 0.31545875 | D24: =C24-B24 -> 0.013370354
A25: Budget Opex | B25: =SUM(Finance_Raw!K:K) -> 60401822 | C25: =B25*(1+$B$13) -> 62213876 | D25: =C25-B25 -> 1812054.7
A26: Opex vs budget (+ = under) | B26: =B25-B22 -> 48856.977 | C26: =C25-C22 -> 1241231
A28: Scenario comparison | B28: Conservative | C28: Base | D28: Aggressive | E28: Custom
A29: Revenue | B29: =$B$16*(1+B$6) -> 87341282 | C29: =$B$16*(1+C$6) -> 89070813 | D29: =$B$16*(1+D$6) -> 90800343 | E29: =$B$16*(1+E$6) -> 89070813
A30: Procurement | B30: =$B$17*(1-B$7) -> 13638679 | C30: =$B$17*(1-C$7) -> 13360339 | D30: =$B$17*(1-D$7) -> 12942828 | E30: =$B$17*(1-E$7) -> 13360339
A31: Agency | B31: =$B$18*(1+B$8) -> 1421551.2 | C31: =$B$18*(1+C$8) -> 1408140.3 | D31: =$B$18*(1+D$8) -> 1381318.6 | E31: =$B$18*(1+E$8) -> 1408140.3
A32: Fleet | B32: =$B$19*(1-B$9) -> 873187.29 | C32: =$B$19*(1-C$9) -> 855547.14 | D32: =$B$19*(1-D$9) -> 837906.99 | E32: =$B$19*(1-E$9) -> 855547.14
A33: Payroll | B33: =$B$20*(1+B$10) -> 39457974 | C33: =$B$20*(1+C$10) -> 39076737 | D33: =$B$20*(1+D$10) -> 38886119 | E33: =$B$20*(1+E$10) -> 39076737
A34: Other Opex | B34: =$B$21*(1+B$11) -> 6332774.2 | C34: =$B$21*(1+C$11) -> 6271882.1 | D34: =$B$21*(1+D$11) -> 6210990 | E34: =$B$21*(1+E$11) -> 6271882.1
A35: Total Opex | B35: =SUM(B30:B34) -> 61724165 | C35: =SUM(C30:C34) -> 60972645 | D35: =SUM(D30:D34) -> 60259163 | E35: =SUM(E30:E34) -> 60972645
A36: EBITDA | B36: =B29-B35 -> 25617117 | C36: =C29-C35 -> 28098167 | D36: =D29-D35 -> 30541180 | E36: =E29-E35 -> 28098167
A37: EBITDA margin | B37: =IFERROR(B36/B29,0) -> 0.29329907 | C37: =IFERROR(C36/C29,0) -> 0.31545875 | D37: =IFERROR(D36/D29,0) -> 0.33635534 | E37: =IFERROR(E36/E29,0) -> 0.31545875
A38: EBITDA vs 2025 | B38: =B36-$B$23 -> -506435.38 | C38: =C36-$B$23 -> 1974614.9 | D38: =D36-$B$23 -> 4417628 | E38: =E36-$B$23 -> 1974614.9
A41: EBITDA bridge 2025 -> 2026 | B41: Value | C41: Base | D41: Increase | E41: Decrease | F41: Total | G41: Running
A42: 2025 EBITDA | B42: =B23 -> 26123553 | C42: =0 -> 0 | D42: =0 -> 0 | E42: =0 -> 0 | F42: =B42 -> 26123553 | G42: =B42 -> 26123553 | H42: Base/Increase/Decrease/Total feed the stacked-column waterfall on the Dashboard.
A43: Revenue growth | B43: =D16 -> 2594295.5 | C43: =MIN(G42,G43) -> 26123553 | D43: =MAX(B43,0) -> 2594295.5 | E43: =MAX(-B43,0) -> 0 | F43: =0 -> 0 | G43: =G42+B43 -> 28717848
A44: Procurement savings | B44: =-D17 -> 556680.77 | C44: =MIN(G43,G44) -> 28717848 | D44: =MAX(B44,0) -> 556680.77 | E44: =MAX(-B44,0) -> 0 | F44: =0 -> 0 | G44: =G43+B44 -> 29274529
A45: Agency rate inflation | B45: =-D18 -> -67054.3 | C45: =MIN(G44,G45) -> 29207474 | D45: =MAX(B45,0) -> 0 | E45: =MAX(-B45,0) -> 67054.3 | F45: =0 -> 0 | G45: =G44+B45 -> 29207474
A46: Fleet efficiency | B46: =-D19 -> 26460.221 | C46: =MIN(G45,G46) -> 29207474 | D46: =MAX(B46,0) -> 26460.221 | E46: =MAX(-B46,0) -> 0 | F46: =0 -> 0 | G46: =G45+B46 -> 29233935
...

Sheet Savings_Tracker
A1: Commercial Savings Tracker (2026 plan vs delivery)
A2: Target = 2025 category spend x target %. Realised YTD values are the monthly input from the savings register (blue cells).
A4: Months elapsed (YTD to Aug-2026) | C4: 8
A5: Status thresholds: On Target >= 100% of target, Watch >= | C5: 0.75
A6: Category | B6: Owner | C6: 2025 Spend | D6: Target % | E6: Target saving | F6: Realised YTD | G6: FY forecast | H6: % of target | I6: Status | J6: Gap to target
A7: Medical Supplies | B7: =IFERROR(INDEX(Category_Targets!$C$2:$C$9,MATCH(A7,Category_Targets!$A$2:$A$9,0)),"") -> Procurement | C7: =SUMIFS(Cleaned_Procurement!$O$2:$O$1801,Cleaned_Procurement!$F$2:$F$1801,A7) -> 1097153 | D7: =IFERROR(INDEX(Category_Targets!$B$2:$B$9,MATCH(A7,Category_Targets!$A$2:$A$9,0)),0) -> 0.06 | E7: =C7*D7 -> 65829.181 | F7: 46100 | G7: =IFERROR(F7/$C$4*12,0) -> 69150 | H7: =IFERROR(G7/E7,0) -> 1.050446 | I7: =IF(H7>=1,"On Target",IF(H7>=$C$5,"Watch","Off Track")) -> On Target | J7: =E7-G7 -> -3320.8194
A8: Food & Catering | B8: =IFERROR(INDEX(Category_Targets!$C$2:$C$9,MATCH(A8,Category_Targets!$A$2:$A$9,0)),"") -> Procurement | C8: =SUMIFS(Cleaned_Procurement!$O$2:$O$1801,Cleaned_Procurement!$F$2:$F$1801,A8) -> 837713.63 | D8: =IFERROR(INDEX(Category_Targets!$B$2:$B$9,MATCH(A8,Category_Targets!$A$2:$A$9,0)),0) -> 0.04 | E8: =C8*D8 -> 33508.545 | F8: 20100 | G8: =IFERROR(F8/$C$4*12,0) -> 30150 | H8: =IFERROR(G8/E8,0) -> 0.89977049 | I8: =IF(H8>=1,"On Target",IF(H8>=$C$5,"Watch","Off Track")) -> Watch | J8: =E8-G8 -> 3358.5452
A9: Facilities | B9: =IFERROR(INDEX(Category_Targets!$C$2:$C$9,MATCH(A9,Category_Targets!$A$2:$A$9,0)),"") -> Facilities | C9: =SUMIFS(Cleaned_Procurement!$O$2:$O$1801,Cleaned_Procurement!$F$2:$F$1801,A9) -> 2128780.9 | D9: =IFERROR(INDEX(Category_Targets!$B$2:$B$9,MATCH(A9,Category_Targets!$A$2:$A$9,0)),0) -> 0.05 | E9: =C9*D9 -> 106439.05 | F9: 49700 | G9: =IFERROR(F9/$C$4*12,0) -> 74550 | H9: =IFERROR(G9/E9,0) -> 0.70040086 | I9: =IF(H9>=1,"On Target",IF(H9>=$C$5,"Watch","Off Track")) -> Off Track | J9: =E9-G9 -> 31889.046
A10: Utilities | B10: =IFERROR(INDEX(Category_Targets!$C$2:$C$9,MATCH(A10,Category_Targets!$A$2:$A$9,0)),"") -> Procurement | C10: =SUMIFS(Cleaned_Procurement!$O$2:$O$1801,Cleaned_Procurement!$F$2:$F$1801,A10) -> 2401261.6 | D10: =IFERROR(INDEX(Category_Targets!$B$2:$B$9,MATCH(A10,Category_Targets!$A$2:$A$9,0)),0) -> 0.03 | E10: =C10*D10 -> 72037.848 | F10: 52800 | G10: =IFERROR(F10/$C$4*12,0) -> 79200 | H10: =IFERROR(G10/E10,0) -> 1.0994221 | I10: =IF(H10>=1,"On Target",IF(H10>=$C$5,"Watch","Off Track")) -> On Target | J10: =E10-G10 -> -7162.152
A11: IT & Telecoms | B11: =IFERROR(INDEX(Category_Targets!$C$2:$C$9,MATCH(A11,Category_Targets!$A$2:$A$9,0)),"") -> IT | C11: =SUMIFS(Cleaned_Procurement!$O$2:$O$1801,Cleaned_Procurement!$F$2:$F$1801,A11) -> 2505155.2 | D11: =IFERROR(INDEX(Category_Targets!$B$2:$B$9,MATCH(A11,Category_Targets!$A$2:$A$9,0)),0) -> 0.08 | E11: =C11*D11 -> 200412.41 | F11: 106900 | G11: =IFERROR(F11/$C$4*12,0) -> 160350 | H11: =IFERROR(G11/E11,0) -> 0.80010014 | I11: =IF(H11>=1,"On Target",IF(H11>=$C$5,"Watch","Off Track")) -> Watch | J11: =E11-G11 -> 40062.414
A12: Vehicle & Fuel | B12: =IFERROR(INDEX(Category_Targets!$C$2:$C$9,MATCH(A12,Category_Targets!$A$2:$A$9,0)),"") -> Fleet | C12: =SUMIFS(Cleaned_Procurement!$O$2:$O$1801,Cleaned_Procurement!$F$2:$F$1801,A12) -> 1030620.3 | D12: =IFERROR(INDEX(Category_Targets!$B$2:$B$9,MATCH(A12,Category_Targets!$A$2:$A$9,0)),0) -> 0.05 | E12: =C12*D12 -> 51531.015 | F12: 32600 | G12: =IFERROR(F12/$C$4*12,0) -> 48900 | H12: =IFERROR(G12/E12,0) -> 0.94894308 | I12: =IF(H12>=1,"On Target",IF(H12>=$C$5,"Watch","Off Track")) -> Watch | J12: =E12-G12 -> 2631.015
A13: Agency Labour | B13: =IFERROR(INDEX(Category_Targets!$C$2:$C$9,MATCH(A13,Category_Targets!$A$2:$A$9,0)),"") -> Workforce | C13: =SUMIFS(Cleaned_Procurement!$O$2:$O$1801,Cleaned_Procurement!$F$2:$F$1801,A13) -> 3193367.1 | D13: =IFERROR(INDEX(Category_Targets!$B$2:$B$9,MATCH(A13,Category_Targets!$A$2:$A$9,0)),0) -> 0.07 | E13: =C13*D13 -> 223535.7 | F13: 89400 | G13: =IFERROR(F13/$C$4*12,0) -> 134100 | H13: =IFERROR(G13/E13,0) -> 0.59990418 | I13: =IF(H13>=1,"On Target",IF(H13>=$C$5,"Watch","Off Track")) -> Off Track | J13: =E13-G13 -> 89435.7
A14: Office & Training | B14: =IFERROR(INDEX(Category_Targets!$C$2:$C$9,MATCH(A14,Category_Targets!$A$2:$A$9,0)),"") -> Commercial | C14: =SUMIFS(Cleaned_Procurement!$O$2:$O$1801,Cleaned_Procurement!$F$2:$F$1801,A14) -> 728629.96 | D14: =IFERROR(INDEX(Category_Targets!$B$2:$B$9,MATCH(A14,Category_Targets!$A$2:$A$9,0)),0) -> 0.04 | E14: =C14*D14 -> 29145.198 | F14: 23300 | G14: =IFERROR(F14/$C$4*12,0) -> 34950 | H14: =IFERROR(G14/E14,0) -> 1.1991684 | I14: =IF(H14>=1,"On Target",IF(H14>=$C$5,"Watch","Off Track")) -> On Target | J14: =E14-G14 -> -5804.8016
A15: Total | C15: =SUM(C7:C14) -> 13922682 | D15: =IFERROR(E15/C15,0) -> 0.056198868 | E15: =SUM(E7:E14) -> 782438.95 | F15: =SUM(F7:F14) -> 420900 | G15: =SUM(G7:G14) -> 631350 | H15: =IFERROR(G15/E15,0) -> 0.80690002 | I15: =IF(H15>=1,"On Target",IF(H15>=$C$5,"Watch","Off Track")) -> Watch | J15: =SUM(J7:J14) -> 151088.95
A17: Status count
A18: On Target | B18: =COUNTIF($I$7:$I$14,A18) -> 3
A19: Watch | B19: =COUNTIF($I$7:$I$14,A19) -> 3
A20: Off Track | B20: =COUNTIF($I$7:$I$14,A20) -> 2
A22: ="Biggest gap: "&INDEX(A7:A14,MATCH(MAX(J7:J14),J7:J14,0))&" is forecast "&TEXT(MAX(J7:J14),"£#,##0")&" short of target. Plan delivers "&TEXT(H15,"0%")&" of the "&TEXT(E15,"£#,##0")&" target." -> Biggest gap: Agency Labour is forecast £89,436 short of target. Plan delivers 81% of the £782,439 target.

Sheet Site_Performance
A1: Site Performance: Budget vs Actual Opex and EBITDA (2025)
A2: Variance = Budget - Actual (positive is favourable). RAG thresholds are inputs.
A4: SiteID | B4: Site | C4: Region | D4: Revenue | E4: Actual Opex | F4: Budget Opex | G4: Variance | H4: Var % | I4: EBITDA margin | J4: Margin rank | K4: Status | L4: RAG thresholds
A5: =Sites!A2 -> S001 | B5: =Sites!B2 -> Preston Care & Education Centre | C5: =Sites!C2 -> North | D5: =SUMIFS(Finance_Raw!$E:$E,Finance_Raw!$B:$B,A5) -> 4539947.5 | E5: =SUMIFS(Finance_Raw!$L:$L,Finance_Raw!$B:$B,A5) -> 3138939.4 | F5: =SUMIFS(Finance_Raw!$K:$K,Finance_Raw!$B:$B,A5) -> 3118796.1 | G5: =F5-E5 -> -20143.333 | H5: =IFERROR(G5/F5,0) -> -0.0064586888 | I5: =IFERROR((D5-E5)/D5,0) -> 0.30859567 | J5: =RANK(I5,$I$5:$I$24,0) -> 4 | K5: =IF(H5<$N$5,"Red",IF(H5<$N$6,"Amber","Green")) -> Amber | L5: Red if overspend worse than | N5: -0.01
A6: =Sites!A3 -> S002 | B6: =Sites!B3 -> Manchester Care & Education Centre | C6: =Sites!C3 -> North | D6: =SUMIFS(Finance_Raw!$E:$E,Finance_Raw!$B:$B,A6) -> 4350391.7 | E6: =SUMIFS(Finance_Raw!$L:$L,Finance_Raw!$B:$B,A6) -> 3074525.5 | F6: =SUMIFS(Finance_Raw!$K:$K,Finance_Raw!$B:$B,A6) -> 3061502.2 | G6: =F6-E6 -> -13023.317 | H6: =IFERROR(G6/F6,0) -> -0.0042538976 | I6: =IFERROR((D6-E6)/D6,0) -> 0.29327617 | J6: =RANK(I6,$I$5:$I$24,0) -> 18 | K6: =IF(H6<$N$5,"Red",IF(H6<$N$6,"Amber","Green")) -> Amber | L6: Amber if overspend worse than | N6: 0
A7: =Sites!A4 -> S003 | B7: =Sites!B4 -> Leeds Care & Education Centre | C7: =Sites!C4 -> North | D7: =SUMIFS(Finance_Raw!$E:$E,Finance_Raw!$B:$B,A7) -> 4134779.6 | E7: =SUMIFS(Finance_Raw!$L:$L,Finance_Raw!$B:$B,A7) -> 2879265.3 | F7: =SUMIFS(Finance_Raw!$K:$K,Finance_Raw!$B:$B,A7) -> 2864950.6 | G7: =F7-E7 -> -14314.657 | H7: =IFERROR(G7/F7,0) -> -0.0049964758 | I7: =IFERROR((D7-E7)/D7,0) -> 0.30364722 | J7: =RANK(I7,$I$5:$I$24,0) -> 10 | K7: =IF(H7<$N$5,"Red",IF(H7<$N$6,"Amber","Green")) -> Amber
A8: =Sites!A5 -> S004 | B8: =Sites!B5 -> Newcastle Care & Education Centre | C8: =Sites!C5 -> North | D8: =SUMIFS(Finance_Raw!$E:$E,Finance_Raw!$B:$B,A8) -> 4200462.6 | E8: =SUMIFS(Finance_Raw!$L:$L,Finance_Raw!$B:$B,A8) -> 2957894.8 | F8: =SUMIFS(Finance_Raw!$K:$K,Finance_Raw!$B:$B,A8) -> 2968153.1 | G8: =F8-E8 -> 10258.353 | H8: =IFERROR(G8/F8,0) -> 0.0034561402 | I8: =IFERROR((D8-E8)/D8,0) -> 0.2958169 | J8: =RANK(I8,$I$5:$I$24,0) -> 15 | K8: =IF(H8<$N$5,"Red",IF(H8<$N$6,"Amber","Green")) -> Green
A9: =Sites!A6 -> S005 | B9: =Sites!B6 -> Sheffield Care & Education Centre | C9: =Sites!C6 -> North | D9: =SUMIFS(Finance_Raw!$E:$E,Finance_Raw!$B:$B,A9) -> 4381089 | E9: =SUMIFS(Finance_Raw!$L:$L,Finance_Raw!$B:$B,A9) -> 3097200.8 | F9: =SUMIFS(Finance_Raw!$K:$K,Finance_Raw!$B:$B,A9) -> 3107939.5 | G9: =F9-E9 -> 10738.757 | H9: =IFERROR(G9/F9,0) -> 0.0034552656 | I9: =IFERROR((D9-E9)/D9,0) -> 0.2930523 | J9: =RANK(I9,$I$5:$I$24,0) -> 19 | K9: =IF(H9<$N$5,"Red",IF(H9<$N$6,"Amber","Green")) -> Green
A10: =Sites!A7 -> S006 | B10: =Sites!B7 -> Birmingham Care & Education Centre | C10: =Sites!C7 -> Midlands | D10: =SUMIFS(Finance_Raw!$E:$E,Finance_Raw!$B:$B,A10) -> 4302157.3 | E10: =SUMIFS(Finance_Raw!$L:$L,Finance_Raw!$B:$B,A10) -> 2999128.9 | F10: =SUMIFS(Finance_Raw!$K:$K,Finance_Raw!$B:$B,A10) -> 2991112.8 | G10: =F10-E10 -> -8016.1267 | H10: =IFERROR(G10/F10,0) -> -0.0026799814 | I10: =IFERROR((D10-E10)/D10,0) -> 0.30287791 | J10: =RANK(I10,$I$5:$I$24,0) -> 11 | K10: =IF(H10<$N$5,"Red",IF(H10<$N$6,"Amber","Green")) -> Amber
A11: =Sites!A8 -> S007 | B11: =Sites!B8 -> Nottingham Care & Education Centre | C11: =Sites!C8 -> Midlands | D11: =SUMIFS(Finance_Raw!$E:$E,Finance_Raw!$B:$B,A11) -> 4817411.2 | E11: =SUMIFS(Finance_Raw!$L:$L,Finance_Raw!$B:$B,A11) -> 3311125.2 | F11: =SUMIFS(Finance_Raw!$K:$K,Finance_Raw!$B:$B,A11) -> 3322611.7 | G11: =F11-E11 -> 11486.46 | H11: =IFERROR(G11/F11,0) -> 0.0034570576 | I11: =IFERROR((D11-E11)/D11,0) -> 0.3126754 | J11: =RANK(I11,$I$5:$I$24,0) -> 1 | K11: =IF(H11<$N$5,"Red",IF(H11<$N$6,"Amber","Green")) -> Green
A12: =Sites!A9 -> S008 | B12: =Sites!B9 -> Leicester Care & Education Centre | C12: =Sites!C9 -> Midlands | D12: =SUMIFS(Finance_Raw!$E:$E,Finance_Raw!$B:$B,A12) -> 4703410.5 | E12: =SUMIFS(Finance_Raw!$L:$L,Finance_Raw!$B:$B,A12) -> 3272108.8 | F12: =SUMIFS(Finance_Raw!$K:$K,Finance_Raw!$B:$B,A12) -> 3251343.4 | G12: =F12-E12 -> -20765.33 | H12: =IFERROR(G12/F12,0) -> -0.0063866923 | I12: =IFERROR((D12-E12)/D12,0) -> 0.30431146 | J12: =RANK(I12,$I$5:$I$24,0) -> 9 | K12: =IF(H12<$N$5,"Red",IF(H12<$N$6,"Amber","Green")) -> Amber
A13: =Sites!A10 -> S009 | B13: =Sites!B10 -> Derby Care & Education Centre | C13: =Sites!C10 -> Midlands | D13: =SUMIFS(Finance_Raw!$E:$E,Finance_Raw!$B:$B,A13) -> 4279128.7 | E13: =SUMIFS(Finance_Raw!$L:$L,Finance_Raw!$B:$B,A13) -> 3005077.6 | F13: =SUMIFS(Finance_Raw!$K:$K,Finance_Raw!$B:$B,A13) -> 2989752.7 | G13: =F13-E13 -> -15324.877 | H13: =IFERROR(G13/F13,0) -> -0.0051258008 | I13: =IFERROR((D13-E13)/D13,0) -> 0.29773611 | J13: =RANK(I13,$I$5:$I$24,0) -> 14 | K13: =IF(H13<$N$5,"Red",IF(H13<$N$6,"Amber","Green")) -> Amber
A14: =Sites!A11 -> S010 | B14: =Sites!B11 -> Coventry Care & Education Centre | C14: =Sites!C11 -> Midlands | D14: =SUMIFS(Finance_Raw!$E:$E,Finance_Raw!$B:$B,A14) -> 4038599.6 | E14: =SUMIFS(Finance_Raw!$L:$L,Finance_Raw!$B:$B,A14) -> 2816401.3 | F14: =SUMIFS(Finance_Raw!$K:$K,Finance_Raw!$B:$B,A14) -> 2835552 | G14: =F14-E14 -> 19150.647 | H14: =IFERROR(G14/F14,0) -> 0.0067537633 | I14: =IFERROR((D14-E14)/D14,0) -> 0.30262923 | J14: =RANK(I14,$I$5:$I$24,0) -> 12 | K14: =IF(H14<$N$5,"Red",IF(H14<$N$6,"Amber","Green")) -> Green
A15: =Sites!A12 -> S011 | B15: =Sites!B12 -> London Care & Education Centre | C15: =Sites!C12 -> South | D15: =SUMIFS(Finance_Raw!$E:$E,Finance_Raw!$B:$B,A15) -> 4422526.7 | E15: =SUMIFS(Finance_Raw!$L:$L,Finance_Raw!$B:$B,A15) -> 3059307.4 | F15: =SUMIFS(Finance_Raw!$K:$K,Finance_Raw!$B:$B,A15) -> 3064550.7 | G15: =F15-E15 -> 5243.3367 | H15: =IFERROR(G15/F15,0) -> 0.0017109642 | I15: =IFERROR((D15-E15)/D15,0) -> 0.30824445 | J15: =RANK(I15,$I$5:$I$24,0) -> 5 | K15: =IF(H15<$N$5,"Red",IF(H15<$N$6,"Amber","Green")) -> Green
A16: =Sites!A13 -> S012 | B16: =Sites!B13 -> Bristol Care & Education Centre | C16: =Sites!C13 -> South | D16: =SUMIFS(Finance_Raw!$E:$E,Finance_Raw!$B:$B,A16) -> 4289982.2 | E16: =SUMIFS(Finance_Raw!$L:$L,Finance_Raw!$B:$B,A16) -> 2963438.8 | F16: =SUMIFS(Finance_Raw!$K:$K,Finance_Raw!$B:$B,A16) -> 2994092.4 | G16: =F16-E16 -> 30653.617 | H16: =IFERROR(G16/F16,0) -> 0.010238033 | I16: =IFERROR((D16-E16)/D16,0) -> 0.30921887 | J16: =RANK(I16,$I$5:$I$24,0) -> 3 | K16: =IF(H16<$N$5,"Red",IF(H16<$N$6,"Amber","Green")) -> Green
A17: =Sites!A14 -> S013 | B17: =Sites!B14 -> Reading Care & Education Centre | C17: =Sites!C14 -> South | D17: =SUMIFS(Finance_Raw!$E:$E,Finance_Raw!$B:$B,A17) -> 4471092.7 | E17: =SUMIFS(Finance_Raw!$L:$L,Finance_Raw!$B:$B,A17) -> 3097431.9 | F17: =SUMIFS(Finance_Raw!$K:$K,Finance_Raw!$B:$B,A17) -> 3101674.4 | G17: =F17-E17 -> 4242.4367 | H17: =IFERROR(G17/F17,0) -> 0.0013677892 | I17: =IFERROR((D17-E17)/D17,0) -> 0.30723155 | J17: =RANK(I17,$I$5:$I$24,0) -> 6 | K17: =IF(H17<$N$5,"Red",IF(H17<$N$6,"Amber","Green")) -> Green
A18: =Sites!A15 -> S014 | B18: =Sites!B15 -> Southampton Care & Education Centre | C18: =Sites!C15 -> South | D18: =SUMIFS(Finance_Raw!$E:$E,Finance_Raw!$B:$B,A18) -> 4273113.4 | E18: =SUMIFS(Finance_Raw!$L:$L,Finance_Raw!$B:$B,A18) -> 2968785.6 | F18: =SUMIFS(Finance_Raw!$K:$K,Finance_Raw!$B:$B,A18) -> 2974770 | G18: =F18-E18 -> 5984.32 | H18: =IFERROR(G18/F18,0) -> 0.0020116917 | I18: =IFERROR((D18-E18)/D18,0) -> 0.30524061 | J18: =RANK(I18,$I$5:$I$24,0) -> 8 | K18: =IF(H18<$N$5,"Red",IF(H18<$N$6,"Amber","Green")) -> Green
... A24: =Sites!A21 -> S020 | B24: =Sites!B21 -> Bangor Care & Education Centre | C24: =Sites!C21 -> Wales | D24: =SUMIFS(Finance_Raw!$E:$E,Finance_Raw!$B:$B,A24) -> 4785341.9 | E24: =SUMIFS(Finance_Raw!$L:$L,Finance_Raw!$B:$B,A24) -> 3304982.8 | F24: =SUMIFS(Finance_Raw!$K:$K,Finance_Raw!$B:$B,A24) -> 3304204.3 | G24: =F24-E24 -> -778.49333 | H24: =IFERROR(G24/F24,0) -> -0.0002356069 | I24: =IFERROR((D24-E24)/D24,0) -> 0.30935285 | J24: =RANK(I24,$I$5:$I$24,0) -> 2 | K24: =IF(H24<$N$5,"Red",IF(H24<$N$6,"Amber","Green")) -> Amber
A25: Total | D25: =SUM(D5:D24) -> 86476517 | E25: =SUM(E5:E24) -> 60352965 | F25: =SUM(F5:F24) -> 60401822 | G25: =SUM(G5:G24) -> 48856.977 | H25: =IFERROR(G25/F25,0) -> 0.00080886595 | I25: =IFERROR((D25-E25)/D25,0) -> 0.3020884
A27: ="Sites over budget: "&COUNTIF(K5:K24,"Red")&" red, "&COUNTIF(K5:K24,"Amber")&" amber. Weakest margin: "&INDEX(B5:B24,MATCH(20,J5:J24,0))&" ("&TEXT(MIN(I5:I24),"0.0%")&"); strongest: "&INDEX(B5:B24,MATCH(1,J5:J24,0))&" ("&TEXT(MAX(I5:I24),"0.0%")&")." -> Sites over budget: 0 red, 8 amber. Weakest margin: Brighton Care & Education Centre (28.9%); strongest: Nottingham Care & Education Centre (31.3%).

Sheet Ops_Analysis
A1: Fleet, Workforce & Agency Analysis (2025, monthly)
A2: Unit-cost KPIs that commercial teams track: cost per mile, overtime share, agency share of staff cost, absence per FTE.
A4: Month | B4: Miles | C4: Fuel cost | D4: Total fleet cost | E4: Cost / mile | F4: FTE | G4: Total payroll | H4: Overtime cost | I4: OT % payroll | J4: Absence days | K4: Absence / FTE | L4: Agency hours | M4: Agency spend | N4: Avg agency rate | O4: Agency % staff cost
A5: 45658 | B5: =SUMIFS(Fleet_Raw!$G:$G,Fleet_Raw!$A:$A,$A5) -> 97426 | C5: =SUMIFS(Fleet_Raw!$I:$I,Fleet_Raw!$A:$A,$A5) -> 15380.86 | D5: =SUMIFS(Fleet_Raw!$L:$L,Fleet_Raw!$A:$A,$A5) -> 70737.9 | E5: =IFERROR(D5/B5,0) -> 0.72606799 | F5: =SUMIFS(Workforce_Raw!$F:$F,Workforce_Raw!$A:$A,$A5) -> 1059.7 | G5: =SUMIFS(Workforce_Raw!$L:$L,Workforce_Raw!$A:$A,$A5) -> 3034099.2 | H5: =SUMIFS(Workforce_Raw!$I:$I,Workforce_Raw!$A:$A,$A5) -> 86782.57 | I5: =IFERROR(H5/G5,0) -> 0.028602416 | J5: =SUMIFS(Workforce_Raw!$J:$J,Workforce_Raw!$A:$A,$A5) -> 512.7 | K5: =IFERROR(J5/F5,0) -> 0.48381617 | L5: =SUMIFS(Agency_Raw!$G:$G,Agency_Raw!$A:$A,$A5) -> 3650 | M5: =SUMIFS(Agency_Raw!$I:$I,Agency_Raw!$A:$A,$A5) -> 107437 | N5: =IFERROR(M5/L5,0) -> 29.434795 | O5: =IFERROR(M5/(M5+G5),0) -> 0.034198873
A6: 45689 | B6: =SUMIFS(Fleet_Raw!$G:$G,Fleet_Raw!$A:$A,$A6) -> 100940 | C6: =SUMIFS(Fleet_Raw!$I:$I,Fleet_Raw!$A:$A,$A6) -> 15703.06 | D6: =SUMIFS(Fleet_Raw!$L:$L,Fleet_Raw!$A:$A,$A6) -> 75544.4 | E6: =IFERROR(D6/B6,0) -> 0.74840896 | F6: =SUMIFS(Workforce_Raw!$F:$F,Workforce_Raw!$A:$A,$A6) -> 1243.9 | G6: =SUMIFS(Workforce_Raw!$L:$L,Workforce_Raw!$A:$A,$A6) -> 3447818.4 | H6: =SUMIFS(Workforce_Raw!$I:$I,Workforce_Raw!$A:$A,$A6) -> 96726.69 | I6: =IFERROR(H6/G6,0) -> 0.028054462 | J6: =SUMIFS(Workforce_Raw!$J:$J,Workforce_Raw!$A:$A,$A6) -> 621.5 | K6: =IFERROR(J6/F6,0) -> 0.49963823 | L6: =SUMIFS(Agency_Raw!$G:$G,Agency_Raw!$A:$A,$A6) -> 3915 | M6: =SUMIFS(Agency_Raw!$I:$I,Agency_Raw!$A:$A,$A6) -> 121421 | N6: =IFERROR(M6/L6,0) -> 31.014304 | O6: =IFERROR(M6/(M6+G6),0) -> 0.034018733
A7: 45717 | B7: =SUMIFS(Fleet_Raw!$G:$G,Fleet_Raw!$A:$A,$A7) -> 101802 | C7: =SUMIFS(Fleet_Raw!$I:$I,Fleet_Raw!$A:$A,$A7) -> 15989.06 | D7: =SUMIFS(Fleet_Raw!$L:$L,Fleet_Raw!$A:$A,$A7) -> 74481.71 | E7: =IFERROR(D7/B7,0) -> 0.73163307 | F7: =SUMIFS(Workforce_Raw!$F:$F,Workforce_Raw!$A:$A,$A7) -> 1129 | G7: =SUMIFS(Workforce_Raw!$L:$L,Workforce_Raw!$A:$A,$A7) -> 3105246.8 | H7: =SUMIFS(Workforce_Raw!$I:$I,Workforce_Raw!$A:$A,$A7) -> 96705.13 | I7: =IFERROR(H7/G7,0) -> 0.031142494 | J7: =SUMIFS(Workforce_Raw!$J:$J,Workforce_Raw!$A:$A,$A7) -> 567.5 | K7: =IFERROR(J7/F7,0) -> 0.50265722 | L7: =SUMIFS(Agency_Raw!$G:$G,Agency_Raw!$A:$A,$A7) -> 3446 | M7: =SUMIFS(Agency_Raw!$I:$I,Agency_Raw!$A:$A,$A7) -> 103588 | N7: =IFERROR(M7/L7,0) -> 30.06036 | O7: =IFERROR(M7/(M7+G7),0) -> 0.032282123
A8: 45748 | B8: =SUMIFS(Fleet_Raw!$G:$G,Fleet_Raw!$A:$A,$A8) -> 108281 | C8: =SUMIFS(Fleet_Raw!$I:$I,Fleet_Raw!$A:$A,$A8) -> 17231.37 | D8: =SUMIFS(Fleet_Raw!$L:$L,Fleet_Raw!$A:$A,$A8) -> 78410.89 | E8: =IFERROR(D8/B8,0) -> 0.72414265 | F8: =SUMIFS(Workforce_Raw!$F:$F,Workforce_Raw!$A:$A,$A8) -> 1164 | G8: =SUMIFS(Workforce_Raw!$L:$L,Workforce_Raw!$A:$A,$A8) -> 3307047.1 | H8: =SUMIFS(Workforce_Raw!$I:$I,Workforce_Raw!$A:$A,$A8) -> 96930.42 | I8: =IFERROR(H8/G8,0) -> 0.029310263 | J8: =SUMIFS(Workforce_Raw!$J:$J,Workforce_Raw!$A:$A,$A8) -> 575 | K8: =IFERROR(J8/F8,0) -> 0.49398625 | L8: =SUMIFS(Agency_Raw!$G:$G,Agency_Raw!$A:$A,$A8) -> 4275 | M8: =SUMIFS(Agency_Raw!$I:$I,Agency_Raw!$A:$A,$A8) -> 132145 | N8: =IFERROR(M8/L8,0) -> 30.911111 | O8: =IFERROR(M8/(M8+G8),0) -> 0.038423268
A9: 45778 | B9: =SUMIFS(Fleet_Raw!$G:$G,Fleet_Raw!$A:$A,$A9) -> 107794 | C9: =SUMIFS(Fleet_Raw!$I:$I,Fleet_Raw!$A:$A,$A9) -> 17162.95 | D9: =SUMIFS(Fleet_Raw!$L:$L,Fleet_Raw!$A:$A,$A9) -> 76044.3 | E9: =IFERROR(D9/B9,0) -> 0.70545949 | F9: =SUMIFS(Workforce_Raw!$F:$F,Workforce_Raw!$A:$A,$A9) -> 1062 | G9: =SUMIFS(Workforce_Raw!$L:$L,Workforce_Raw!$A:$A,$A9) -> 2990128.1 | H9: =SUMIFS(Workforce_Raw!$I:$I,Workforce_Raw!$A:$A,$A9) -> 87244.73 | I9: =IFERROR(H9/G9,0) -> 0.02917759 | J9: =SUMIFS(Workforce_Raw!$J:$J,Workforce_Raw!$A:$A,$A9) -> 541.7 | K9: =IFERROR(J9/F9,0) -> 0.51007533 | L9: =SUMIFS(Agency_Raw!$G:$G,Agency_Raw!$A:$A,$A9) -> 3122 | M9: =SUMIFS(Agency_Raw!$I:$I,Agency_Raw!$A:$A,$A9) -> 99849 | N9: =IFERROR(M9/L9,0) -> 31.982383 | O9: =IFERROR(M9/(M9+G9),0) -> 0.032313832
A10: 45809 | B10: =SUMIFS(Fleet_Raw!$G:$G,Fleet_Raw!$A:$A,$A10) -> 98456 | C10: =SUMIFS(Fleet_Raw!$I:$I,Fleet_Raw!$A:$A,$A10) -> 15588.25 | D10: =SUMIFS(Fleet_Raw!$L:$L,Fleet_Raw!$A:$A,$A10) -> 71812.63 | E10: =IFERROR(D10/B10,0) -> 0.72938805 | F10: =SUMIFS(Workforce_Raw!$F:$F,Workforce_Raw!$A:$A,$A10) -> 1107.2 | G10: =SUMIFS(Workforce_Raw!$L:$L,Workforce_Raw!$A:$A,$A10) -> 3139595.7 | H10: =SUMIFS(Workforce_Raw!$I:$I,Workforce_Raw!$A:$A,$A10) -> 93237.38 | I10: =IFERROR(H10/G10,0) -> 0.029697257 | J10: =SUMIFS(Workforce_Raw!$J:$J,Workforce_Raw!$A:$A,$A10) -> 555.5 | K10: =IFERROR(J10/F10,0) -> 0.50171604 | L10: =SUMIFS(Agency_Raw!$G:$G,Agency_Raw!$A:$A,$A10) -> 3325 | M10: =SUMIFS(Agency_Raw!$I:$I,Agency_Raw!$A:$A,$A10) -> 106117 | N10: =IFERROR(M10/L10,0) -> 31.914887 | O10: =IFERROR(M10/(M10+G10),0) -> 0.032694514
A11: 45839 | B11: =SUMIFS(Fleet_Raw!$G:$G,Fleet_Raw!$A:$A,$A11) -> 89990 | C11: =SUMIFS(Fleet_Raw!$I:$I,Fleet_Raw!$A:$A,$A11) -> 14538.67 | D11: =SUMIFS(Fleet_Raw!$L:$L,Fleet_Raw!$A:$A,$A11) -> 68464.21 | E11: =IFERROR(D11/B11,0) -> 0.76079798 | F11: =SUMIFS(Workforce_Raw!$F:$F,Workforce_Raw!$A:$A,$A11) -> 1030.6 | G11: =SUMIFS(Workforce_Raw!$L:$L,Workforce_Raw!$A:$A,$A11) -> 2935268.2 | H11: =SUMIFS(Workforce_Raw!$I:$I,Workforce_Raw!$A:$A,$A11) -> 76968.2 | I11: =IFERROR(H11/G11,0) -> 0.026221863 | J11: =SUMIFS(Workforce_Raw!$J:$J,Workforce_Raw!$A:$A,$A11) -> 510.6 | K11: =IFERROR(J11/F11,0) -> 0.49543955 | L11: =SUMIFS(Agency_Raw!$G:$G,Agency_Raw!$A:$A,$A11) -> 3831 | M11: =SUMIFS(Agency_Raw!$I:$I,Agency_Raw!$A:$A,$A11) -> 118232 | N11: =IFERROR(M11/L11,0) -> 30.861916 | O11: =IFERROR(M11/(M11+G11),0) -> 0.038720155
A12: 45870 | B12: =SUMIFS(Fleet_Raw!$G:$G,Fleet_Raw!$A:$A,$A12) -> 102951 | C12: =SUMIFS(Fleet_Raw!$I:$I,Fleet_Raw!$A:$A,$A12) -> 16353.71 | D12: =SUMIFS(Fleet_Raw!$L:$L,Fleet_Raw!$A:$A,$A12) -> 76668.93 | E12: =IFERROR(D12/B12,0) -> 0.74471282 | F12: =SUMIFS(Workforce_Raw!$F:$F,Workforce_Raw!$A:$A,$A12) -> 1169.8 | G12: =SUMIFS(Workforce_Raw!$L:$L,Workforce_Raw!$A:$A,$A12) -> 3316445.3 | H12: =SUMIFS(Workforce_Raw!$I:$I,Workforce_Raw!$A:$A,$A12) -> 99012 | I12: =IFERROR(H12/G12,0) -> 0.029854857 | J12: =SUMIFS(Workforce_Raw!$J:$J,Workforce_Raw!$A:$A,$A12) -> 581 | K12: =IFERROR(J12/F12,0) -> 0.4966661 | L12: =SUMIFS(Agency_Raw!$G:$G,Agency_Raw!$A:$A,$A12) -> 3215 | M12: =SUMIFS(Agency_Raw!$I:$I,Agency_Raw!$A:$A,$A12) -> 99862 | N12: =IFERROR(M12/L12,0) -> 31.061275 | O12: =IFERROR(M12/(M12+G12),0) -> 0.029230977
A13: 45901 | B13: =SUMIFS(Fleet_Raw!$G:$G,Fleet_Raw!$A:$A,$A13) -> 96045 | C13: =SUMIFS(Fleet_Raw!$I:$I,Fleet_Raw!$A:$A,$A13) -> 15328.05 | D13: =SUMIFS(Fleet_Raw!$L:$L,Fleet_Raw!$A:$A,$A13) -> 67510.39 | E13: =IFERROR(D13/B13,0) -> 0.70290374 | F13: =SUMIFS(Workforce_Raw!$F:$F,Workforce_Raw!$A:$A,$A13) -> 1113.7 | G13: =SUMIFS(Workforce_Raw!$L:$L,Workforce_Raw!$A:$A,$A13) -> 3167691.7 | H13: =SUMIFS(Workforce_Raw!$I:$I,Workforce_Raw!$A:$A,$A13) -> 87250.03 | I13: =IFERROR(H13/G13,0) -> 0.027543725 | J13: =SUMIFS(Workforce_Raw!$J:$J,Workforce_Raw!$A:$A,$A13) -> 533.3 | K13: =IFERROR(J13/F13,0) -> 0.47885427 | L13: =SUMIFS(Agency_Raw!$G:$G,Agency_Raw!$A:$A,$A13) -> 3980 | M13: =SUMIFS(Agency_Raw!$I:$I,Agency_Raw!$A:$A,$A13) -> 120617 | N13: =IFERROR(M13/L13,0) -> 30.305779 | O13: =IFERROR(M13/(M13+G13),0) -> 0.036680559
A14: 45931 | B14: =SUMIFS(Fleet_Raw!$G:$G,Fleet_Raw!$A:$A,$A14) -> 104371 | C14: =SUMIFS(Fleet_Raw!$I:$I,Fleet_Raw!$A:$A,$A14) -> 16513.5 | D14: =SUMIFS(Fleet_Raw!$L:$L,Fleet_Raw!$A:$A,$A14) -> 74269.95 | E14: =IFERROR(D14/B14,0) -> 0.71159565 | F14: =SUMIFS(Workforce_Raw!$F:$F,Workforce_Raw!$A:$A,$A14) -> 1177.8 | G14: =SUMIFS(Workforce_Raw!$L:$L,Workforce_Raw!$A:$A,$A14) -> 3324296.6 | H14: =SUMIFS(Workforce_Raw!$I:$I,Workforce_Raw!$A:$A,$A14) -> 108904.98 | I14: =IFERROR(H14/G14,0) -> 0.032760307 | J14: =SUMIFS(Workforce_Raw!$J:$J,Workforce_Raw!$A:$A,$A14) -> 587.3 | K14: =IFERROR(J14/F14,0) -> 0.49864154 | L14: =SUMIFS(Agency_Raw!$G:$G,Agency_Raw!$A:$A,$A14) -> 3462 | M14: =SUMIFS(Agency_Raw!$I:$I,Agency_Raw!$A:$A,$A14) -> 103394 | N14: =IFERROR(M14/L14,0) -> 29.865396 | O14: =IFERROR(M14/(M14+G14),0) -> 0.030164332
A15: 45962 | B15: =SUMIFS(Fleet_Raw!$G:$G,Fleet_Raw!$A:$A,$A15) -> 99939 | C15: =SUMIFS(Fleet_Raw!$I:$I,Fleet_Raw!$A:$A,$A15) -> 15667.1 | D15: =SUMIFS(Fleet_Raw!$L:$L,Fleet_Raw!$A:$A,$A15) -> 74181.37 | E15: =IFERROR(D15/B15,0) -> 0.74226648 | F15: =SUMIFS(Workforce_Raw!$F:$F,Workforce_Raw!$A:$A,$A15) -> 1095.2 | G15: =SUMIFS(Workforce_Raw!$L:$L,Workforce_Raw!$A:$A,$A15) -> 3031071.7 | H15: =SUMIFS(Workforce_Raw!$I:$I,Workforce_Raw!$A:$A,$A15) -> 91455.04 | I15: =IFERROR(H15/G15,0) -> 0.03017251 | J15: =SUMIFS(Workforce_Raw!$J:$J,Workforce_Raw!$A:$A,$A15) -> 538.4 | K15: =IFERROR(J15/F15,0) -> 0.49159971 | L15: =SUMIFS(Agency_Raw!$G:$G,Agency_Raw!$A:$A,$A15) -> 3417 | M15: =SUMIFS(Agency_Raw!$I:$I,Agency_Raw!$A:$A,$A15) -> 109315 | N15: =IFERROR(M15/L15,0) -> 31.991513 | O15: =IFERROR(M15/(M15+G15),0) -> 0.034809407
A16: 45992 | B16: =SUMIFS(Fleet_Raw!$G:$G,Fleet_Raw!$A:$A,$A16) -> 104534 | C16: =SUMIFS(Fleet_Raw!$I:$I,Fleet_Raw!$A:$A,$A16) -> 16488.05 | D16: =SUMIFS(Fleet_Raw!$L:$L,Fleet_Raw!$A:$A,$A16) -> 73880.68 | E16: =IFERROR(D16/B16,0) -> 0.7067622 | F16: =SUMIFS(Workforce_Raw!$F:$F,Workforce_Raw!$A:$A,$A16) -> 1206.5 | G16: =SUMIFS(Workforce_Raw!$L:$L,Workforce_Raw!$A:$A,$A16) -> 3324937.3 | H16: =SUMIFS(Workforce_Raw!$I:$I,Workforce_Raw!$A:$A,$A16) -> 95670.62 | I16: =IFERROR(H16/G16,0) -> 0.028773662 | J16: =SUMIFS(Workforce_Raw!$J:$J,Workforce_Raw!$A:$A,$A16) -> 596.4 | K16: =IFERROR(J16/F16,0) -> 0.49432242 | L16: =SUMIFS(Agency_Raw!$G:$G,Agency_Raw!$A:$A,$A16) -> 3898 | M16: =SUMIFS(Agency_Raw!$I:$I,Agency_Raw!$A:$A,$A16) -> 119109 | N16: =IFERROR(M16/L16,0) -> 30.556439 | O16: =IFERROR(M16/(M16+G16),0) -> 0.03458403
A17: FY 2025 | B17: =SUM(B5:B16) -> 1212529 | C17: =SUM(C5:C16) -> 191944.63 | D17: =SUM(D5:D16) -> 882007.36 | E17: =IFERROR(D17/B17,0) -> 0.72741135 | F17: =AVERAGE(F5:F16) -> 1129.95 | G17: =SUM(G5:G16) -> 38123646 | H17: =SUM(H5:H16) -> 1116887.8 | I17: =IFERROR(H17/G17,0) -> 0.029296458 | J17: =SUM(J5:J16) -> 6720.9 | K17: =IFERROR(J17/F17,0) -> 5.9479623 | L17: =SUM(L5:L16) -> 43536 | M17: =SUM(M5:M16) -> 1341086 | N17: =IFERROR(M17/L17,0) -> 30.80407 | O17: =IFERROR(M17/(M17+G17),0) -> 0.033981885
A20: By region | J20: Cost per mile by vehicle type
A21: Region | B21: Fleet cost | C21: Cost / mile | D21: Payroll | E21: OT % payroll | F21: Agency spend | G21: Agency % staff cost | H21: Absence / FTE | J21: Vehicle type | K21: Miles | L21: Total cost | M21: Cost / mile
A22: North | B22: =SUMIFS(Fleet_Raw!$L:$L,Fleet_Raw!$D:$D,A22) -> 217356.61 | C22: =IFERROR(B22/SUMIFS(Fleet_Raw!$G:$G,Fleet_Raw!$D:$D,A22),0) -> 0.70925416 | D22: =SUMIFS(Workforce_Raw!$L:$L,Workforce_Raw!$D:$D,A22) -> 9715710 | E22: =IFERROR(SUMIFS(Workforce_Raw!$I:$I,Workforce_Raw!$D:$D,A22)/D22,0) -> 0.030082033 | F22: =SUMIFS(Agency_Raw!$I:$I,Agency_Raw!$D:$D,A22) -> 344891 | G22: =IFERROR(F22/(F22+D22),0) -> 0.034281352 | H22: =IFERROR(SUMIFS(Workforce_Raw!$J:$J,Workforce_Raw!$D:$D,A22)/(SUMIFS(Workforce_Raw!$F:$F,Workforce_Raw!$D:$D,A22)/12),0) -> 5.9661135 | J22: Car | K22: =SUMIFS(Fleet_Raw!$G:$G,Fleet_Raw!$F:$F,J22) -> 280500 | L22: =SUMIFS(Fleet_Raw!$L:$L,Fleet_Raw!$F:$F,J22) -> 192618.59 | M22: =IFERROR(L22/K22,0) -> 0.68669729
A23: Midlands | B23: =SUMIFS(Fleet_Raw!$L:$L,Fleet_Raw!$D:$D,A23) -> 211540.15 | C23: =IFERROR(B23/SUMIFS(Fleet_Raw!$G:$G,Fleet_Raw!$D:$D,A23),0) -> 0.7440449 | D23: =SUMIFS(Workforce_Raw!$L:$L,Workforce_Raw!$D:$D,A23) -> 9763624.5 | E23: =IFERROR(SUMIFS(Workforce_Raw!$I:$I,Workforce_Raw!$D:$D,A23)/D23,0) -> 0.029567176 | F23: =SUMIFS(Agency_Raw!$I:$I,Agency_Raw!$D:$D,A23) -> 361621 | G23: =IFERROR(F23/(F23+D23),0) -> 0.035714788 | H23: =IFERROR(SUMIFS(Workforce_Raw!$J:$J,Workforce_Raw!$D:$D,A23)/(SUMIFS(Workforce_Raw!$F:$F,Workforce_Raw!$D:$D,A23)/12),0) -> 5.8570724 | J23: Van | K23: =SUMIFS(Fleet_Raw!$G:$G,Fleet_Raw!$F:$F,J23) -> 323951 | L23: =SUMIFS(Fleet_Raw!$L:$L,Fleet_Raw!$F:$F,J23) -> 234814.65 | M23: =IFERROR(L23/K23,0) -> 0.7248462
A24: South | B24: =SUMIFS(Fleet_Raw!$L:$L,Fleet_Raw!$D:$D,A24) -> 215340 | C24: =IFERROR(B24/SUMIFS(Fleet_Raw!$G:$G,Fleet_Raw!$D:$D,A24),0) -> 0.74304111 | D24: =SUMIFS(Workforce_Raw!$L:$L,Workforce_Raw!$D:$D,A24) -> 9333500.1 | E24: =IFERROR(SUMIFS(Workforce_Raw!$I:$I,Workforce_Raw!$D:$D,A24)/D24,0) -> 0.029021814 | F24: =SUMIFS(Agency_Raw!$I:$I,Agency_Raw!$D:$D,A24) -> 327359 | G24: =IFERROR(F24/(F24+D24),0) -> 0.033885082 | H24: =IFERROR(SUMIFS(Workforce_Raw!$J:$J,Workforce_Raw!$D:$D,A24)/(SUMIFS(Workforce_Raw!$F:$F,Workforce_Raw!$D:$D,A24)/12),0) -> 5.933522 | J24: MPV | K24: =SUMIFS(Fleet_Raw!$G:$G,Fleet_Raw!$F:$F,J24) -> 297722 | L24: =SUMIFS(Fleet_Raw!$L:$L,Fleet_Raw!$F:$F,J24) -> 202571 | M24: =IFERROR(L24/K24,0) -> 0.68040319
A25: Wales | B25: =SUMIFS(Fleet_Raw!$L:$L,Fleet_Raw!$D:$D,A25) -> 237770.6 | C25: =IFERROR(B25/SUMIFS(Fleet_Raw!$G:$G,Fleet_Raw!$D:$D,A25),0) -> 0.71628222 | D25: =SUMIFS(Workforce_Raw!$L:$L,Workforce_Raw!$D:$D,A25) -> 9310811.6 | E25: =IFERROR(SUMIFS(Workforce_Raw!$I:$I,Workforce_Raw!$D:$D,A25)/D25,0) -> 0.02846815 | F25: =SUMIFS(Agency_Raw!$I:$I,Agency_Raw!$D:$D,A25) -> 307215 | G25: =IFERROR(F25/(F25+D25),0) -> 0.031941584 | H25: =IFERROR(SUMIFS(Workforce_Raw!$J:$J,Workforce_Raw!$D:$D,A25)/(SUMIFS(Workforce_Raw!$F:$F,Workforce_Raw!$D:$D,A25)/12),0) -> 6.0373787 | J25: Minibus | K25: =SUMIFS(Fleet_Raw!$G:$G,Fleet_Raw!$F:$F,J25) -> 310356 | L25: =SUMIFS(Fleet_Raw!$L:$L,Fleet_Raw!$F:$F,J25) -> 252003.12 | M25: =IFERROR(L25/K25,0) -> 0.81198082
A28: Agency rate by agency and role (average £/hour)
A29: Agency | B29: Registered Nurse | C29: Senior Support Worker | D29: Support Worker | E29: Total spend
A30: CareTemps | B30: =IFERROR(SUMIFS(Agency_Raw!$I:$I,Agency_Raw!$E:$E,$A30,Agency_Raw!$F:$F,B$29)/SUMIFS(Agency_Raw!$G:$G,Agency_Raw!$E:$E,$A30,Agency_Raw!$F:$F,B$29),0) -> 42 | C30: =IFERROR(SUMIFS(Agency_Raw!$I:$I,Agency_Raw!$E:$E,$A30,Agency_Raw!$F:$F,C$29)/SUMIFS(Agency_Raw!$G:$G,Agency_Raw!$E:$E,$A30,Agency_Raw!$F:$F,C$29),0) -> 28 | D30: =IFERROR(SUMIFS(Agency_Raw!$I:$I,Agency_Raw!$E:$E,$A30,Agency_Raw!$F:$F,D$29)/SUMIFS(Agency_Raw!$G:$G,Agency_Raw!$E:$E,$A30,Agency_Raw!$F:$F,D$29),0) -> 23 | E30: =SUMIFS(Agency_Raw!$I:$I,Agency_Raw!$E:$E,$A30) -> 347539
A31: HealthStaffing | B31: =IFERROR(SUMIFS(Agency_Raw!$I:$I,Agency_Raw!$E:$E,$A31,Agency_Raw!$F:$F,B$29)/SUMIFS(Agency_Raw!$G:$G,Agency_Raw!$E:$E,$A31,Agency_Raw!$F:$F,B$29),0) -> 42 | C31: =IFERROR(SUMIFS(Agency_Raw!$I:$I,Agency_Raw!$E:$E,$A31,Agency_Raw!$F:$F,C$29)/SUMIFS(Agency_Raw!$G:$G,Agency_Raw!$E:$E,$A31,Agency_Raw!$F:$F,C$29),0) -> 28 | D31: =IFERROR(SUMIFS(Agency_Raw!$I:$I,Agency_Raw!$E:$E,$A31,Agency_Raw!$F:$F,D$29)/SUMIFS(Agency_Raw!$G:$G,Agency_Raw!$E:$E,$A31,Agency_Raw!$F:$F,D$29),0) -> 23 | E31: =SUMIFS(Agency_Raw!$I:$I,Agency_Raw!$E:$E,$A31) -> 514753
A32: NurseLink | B32: =IFERROR(SUMIFS(Agency_Raw!$I:$I,Agency_Raw!$E:$E,$A32,Agency_Raw!$F:$F,B$29)/SUMIFS(Agency_Raw!$G:$G,Agency_Raw!$E:$E,$A32,Agency_Raw!$F:$F,B$29),0) -> 42 | C32: =IFERROR(SUMIFS(Agency_Raw!$I:$I,Agency_Raw!$E:$E,$A32,Agency_Raw!$F:$F,C$29)/SUMIFS(Agency_Raw!$G:$G,Agency_Raw!$E:$E,$A32,Agency_Raw!$F:$F,C$29),0) -> 28 | D32: =IFERROR(SUMIFS(Agency_Raw!$I:$I,Agency_Raw!$E:$E,$A32,Agency_Raw!$F:$F,D$29)/SUMIFS(Agency_Raw!$G:$G,Agency_Raw!$E:$E,$A32,Agency_Raw!$F:$F,D$29),0) -> 23 | E32: =SUMIFS(Agency_Raw!$I:$I,Agency_Raw!$E:$E,$A32) -> 478794
A34: =IF(AND(MAX(B30:B32)=MIN(B30:B32),MAX(C30:C32)=MIN(C30:C32),MAX(D30:D32)=MIN(D30:D32)),"All three agencies charge identical rates by role, so the lever is volume and grade mix rather than rate: registered nurses are "&TEXT(SUMIFS(Agency_Raw!$I:$I,Agency_Raw!$F:$F,"Registered Nurse")/SUM(Agency_Raw!$I:$I),"0%")&" of agency spend.","Nurse rates range from "&TEXT(MIN(B30:B32),"£0.00")&" to "&TEXT(MAX(B30:B32),"£0.00")&"/hr across agencies: a rate-card conversation worth having.") -> All three agencies charge identical rates by role, so the lever is volume and grade mix rather than rate: registered nurses are 44% of agency spend.

Sheet Supplier_Analysis
A1: Supplier Spend, Concentration & Contract Compliance (2025)
A2: Supplier list is driven by the Supplier_Lookup master; ranking uses RANK and INDEX/MATCH.
A4: Supplier | B4: Category | C4: Contracted | D4: Spend | E4: Invoices | F4: Avg invoice | G4: Share | H4: Rank | I4: Avg terms (days) | K4: Top 10 suppliers (Pareto)
A5: =Supplier_Lookup!A2 -> AutoCare | B5: =Supplier_Lookup!B2 -> Vehicle & Fuel | C5: =Supplier_Lookup!C2 -> N | D5: =SUMIFS(Cleaned_Procurement!$O$2:$O$1801,Cleaned_Procurement!$E$2:$E$1801,A5) -> 284264.57 | E5: =COUNTIFS(Cleaned_Procurement!$E$2:$E$1801,A5) -> 57 | F5: =IFERROR(D5/E5,0) -> 4987.0977 | G5: =IFERROR(D5/$D$29,0) -> 0.020418398 | H5: =RANK(D5,$D$5:$D$28,0) -> 20 | I5: =IFERROR(AVERAGEIFS(Cleaned_Procurement!$K$2:$K$1801,Cleaned_Procurement!$E$2:$E$1801,A5),0) -> 49.210526 | K5: Rank | L5: Supplier | M5: Spend | N5: Share | O5: Cumulative | P5: Contracted
A6: =Supplier_Lookup!A3 -> BuildCare | B6: =Supplier_Lookup!B3 -> Facilities | C6: =Supplier_Lookup!C3 -> N | D6: =SUMIFS(Cleaned_Procurement!$O$2:$O$1801,Cleaned_Procurement!$E$2:$E$1801,A6) -> 647209.95 | E6: =COUNTIFS(Cleaned_Procurement!$E$2:$E$1801,A6) -> 68 | F6: =IFERROR(D6/E6,0) -> 9517.7934 | G6: =IFERROR(D6/$D$29,0) -> 0.046488349 | H6: =RANK(D6,$D$5:$D$28,0) -> 10 | I6: =IFERROR(AVERAGEIFS(Cleaned_Procurement!$K$2:$K$1801,Cleaned_Procurement!$E$2:$E$1801,A6),0) -> 43.897059 | K6: 1 | L6: =INDEX($A$5:$A$28,MATCH(K6,$H$5:$H$28,0)) -> NurseLink | M6: =INDEX($D$5:$D$28,MATCH(K6,$H$5:$H$28,0)) -> 1161388.4 | N6: =IFERROR(M6/$D$29,0) -> 0.083421198 | O6: =SUM($N$6:N6) -> 0.083421198 | P6: =INDEX($C$5:$C$28,MATCH(K6,$H$5:$H$28,0)) -> N
A7: =Supplier_Lookup!A4 -> CareMed | B7: =Supplier_Lookup!B4 -> Medical Supplies | C7: =Supplier_Lookup!C4 -> N | D7: =SUMIFS(Cleaned_Procurement!$O$2:$O$1801,Cleaned_Procurement!$E$2:$E$1801,A7) -> 311670.19 | E7: =COUNTIFS(Cleaned_Procurement!$E$2:$E$1801,A7) -> 62 | F7: =IFERROR(D7/E7,0) -> 5026.9385 | G7: =IFERROR(D7/$D$29,0) -> 0.022386913 | H7: =RANK(D7,$D$5:$D$28,0) -> 18 | I7: =IFERROR(AVERAGEIFS(Cleaned_Procurement!$K$2:$K$1801,Cleaned_Procurement!$E$2:$E$1801,A7),0) -> 47.419355 | K7: 2 | L7: =INDEX($A$5:$A$28,MATCH(K7,$H$5:$H$28,0)) -> HealthStaffing | M7: =INDEX($D$5:$D$28,MATCH(K7,$H$5:$H$28,0)) -> 1072844.7 | N7: =IFERROR(M7/$D$29,0) -> 0.077061205 | O7: =SUM($N$6:N7) -> 0.1604824 | P7: =INDEX($C$5:$C$28,MATCH(K7,$H$5:$H$28,0)) -> N
A8: =Supplier_Lookup!A5 -> CareTemps | B8: =Supplier_Lookup!B5 -> Agency Labour | C8: =Supplier_Lookup!C5 -> N | D8: =SUMIFS(Cleaned_Procurement!$O$2:$O$1801,Cleaned_Procurement!$E$2:$E$1801,A8) -> 959134.04 | E8: =COUNTIFS(Cleaned_Procurement!$E$2:$E$1801,A8) -> 73 | F8: =IFERROR(D8/E8,0) -> 13138.822 | G8: =IFERROR(D8/$D$29,0) -> 0.068893499 | H8: =RANK(D8,$D$5:$D$28,0) -> 4 | I8: =IFERROR(AVERAGEIFS(Cleaned_Procurement!$K$2:$K$1801,Cleaned_Procurement!$E$2:$E$1801,A8),0) -> 45.205479 | K8: 3 | L8: =INDEX($A$5:$A$28,MATCH(K8,$H$5:$H$28,0)) -> PowerDirect | M8: =INDEX($D$5:$D$28,MATCH(K8,$H$5:$H$28,0)) -> 1048249.1 | N8: =IFERROR(M8/$D$29,0) -> 0.075294533 | O8: =SUM($N$6:N8) -> 0.23577694 | P8: =INDEX($C$5:$C$28,MATCH(K8,$H$5:$H$28,0)) -> N
A9: =Supplier_Lookup!A6 -> CleanWorks | B9: =Supplier_Lookup!B6 -> Facilities | C9: =Supplier_Lookup!C6 -> Y | D9: =SUMIFS(Cleaned_Procurement!$O$2:$O$1801,Cleaned_Procurement!$E$2:$E$1801,A9) -> 591363.92 | E9: =COUNTIFS(Cleaned_Procurement!$E$2:$E$1801,A9) -> 73 | F9: =IFERROR(D9/E9,0) -> 8100.8756 | G9: =IFERROR(D9/$D$29,0) -> 0.042476993 | H9: =RANK(D9,$D$5:$D$28,0) -> 11 | I9: =IFERROR(AVERAGEIFS(Cleaned_Procurement!$K$2:$K$1801,Cleaned_Procurement!$E$2:$E$1801,A9),0) -> 45.205479 | K9: 4 | L9: =INDEX($A$5:$A$28,MATCH(K9,$H$5:$H$28,0)) -> CareTemps | M9: =INDEX($D$5:$D$28,MATCH(K9,$H$5:$H$28,0)) -> 959134.04 | N9: =IFERROR(M9/$D$29,0) -> 0.068893499 | O9: =SUM($N$6:N9) -> 0.30467043 | P9: =INDEX($C$5:$C$28,MATCH(K9,$H$5:$H$28,0)) -> N
A10: =Supplier_Lookup!A7 -> ClinEquip | B10: =Supplier_Lookup!B7 -> Medical Supplies | C10: =Supplier_Lookup!C7 -> N | D10: =SUMIFS(Cleaned_Procurement!$O$2:$O$1801,Cleaned_Procurement!$E$2:$E$1801,A10) -> 359940.88 | E10: =COUNTIFS(Cleaned_Procurement!$E$2:$E$1801,A10) -> 67 | F10: =IFERROR(D10/E10,0) -> 5372.2519 | G10: =IFERROR(D10/$D$29,0) -> 0.025854141 | H10: =RANK(D10,$D$5:$D$28,0) -> 15 | I10: =IFERROR(AVERAGEIFS(Cleaned_Procurement!$K$2:$K$1801,Cleaned_Procurement!$E$2:$E$1801,A10),0) -> 43.880597 | K10: 5 | L10: =INDEX($A$5:$A$28,MATCH(K10,$H$5:$H$28,0)) -> SafeGuard FM | M10: =INDEX($D$5:$D$28,MATCH(K10,$H$5:$H$28,0)) -> 890207.06 | N10: =IFERROR(M10/$D$29,0) -> 0.063942553 | O10: =SUM($N$6:N10) -> 0.36861299 | P10: =INDEX($C$5:$C$28,MATCH(K10,$H$5:$H$28,0)) -> N
A11: =Supplier_Lookup!A8 -> CloudLink | B11: =Supplier_Lookup!B8 -> IT & Telecoms | C11: =Supplier_Lookup!C8 -> Y | D11: =SUMIFS(Cleaned_Procurement!$O$2:$O$1801,Cleaned_Procurement!$E$2:$E$1801,A11) -> 881477.21 | E11: =COUNTIFS(Cleaned_Procurement!$E$2:$E$1801,A11) -> 82 | F11: =IFERROR(D11/E11,0) -> 10749.722 | G11: =IFERROR(D11/$D$29,0) -> 0.063315498 | H11: =RANK(D11,$D$5:$D$28,0) -> 6 | I11: =IFERROR(AVERAGEIFS(Cleaned_Procurement!$K$2:$K$1801,Cleaned_Procurement!$E$2:$E$1801,A11),0) -> 44.634146 | K11: 6 | L11: =INDEX($A$5:$A$28,MATCH(K11,$H$5:$H$28,0)) -> CloudLink | M11: =INDEX($D$5:$D$28,MATCH(K11,$H$5:$H$28,0)) -> 881477.21 | N11: =IFERROR(M11/$D$29,0) -> 0.063315498 | O11: =SUM($N$6:N11) -> 0.43192848 | P11: =INDEX($C$5:$C$28,MATCH(K11,$H$5:$H$28,0)) -> Y
A12: =Supplier_Lookup!A9 -> FleetFuel | B12: =Supplier_Lookup!B9 -> Vehicle & Fuel | C12: =Supplier_Lookup!C9 -> Y | D12: =SUMIFS(Cleaned_Procurement!$O$2:$O$1801,Cleaned_Procurement!$E$2:$E$1801,A12) -> 314243.92 | E12: =COUNTIFS(Cleaned_Procurement!$E$2:$E$1801,A12) -> 74 | F12: =IFERROR(D12/E12,0) -> 4246.5395 | G12: =IFERROR(D12/$D$29,0) -> 0.022571781 | H12: =RANK(D12,$D$5:$D$28,0) -> 17 | I12: =IFERROR(AVERAGEIFS(Cleaned_Procurement!$K$2:$K$1801,Cleaned_Procurement!$E$2:$E$1801,A12),0) -> 44.797297 | K12: 7 | L12: =INDEX($A$5:$A$28,MATCH(K12,$H$5:$H$28,0)) -> NetServe | M12: =INDEX($D$5:$D$28,MATCH(K12,$H$5:$H$28,0)) -> 851726.08 | N12: =IFERROR(M12/$D$29,0) -> 0.061178508 | O12: =SUM($N$6:N12) -> 0.49310699 | P12: =INDEX($C$5:$C$28,MATCH(K12,$H$5:$H$28,0)) -> N
A13: =Supplier_Lookup!A10 -> FreshServe | B13: =Supplier_Lookup!B10 -> Food & Catering | C13: =Supplier_Lookup!C10 -> Y | D13: =SUMIFS(Cleaned_Procurement!$O$2:$O$1801,Cleaned_Procurement!$E$2:$E$1801,A13) -> 238615.67 | E13: =COUNTIFS(Cleaned_Procurement!$E$2:$E$1801,A13) -> 74 | F13: =IFERROR(D13/E13,0) -> 3224.5361 | G13: =IFERROR(D13/$D$29,0) -> 0.01713949 | H13: =RANK(D13,$D$5:$D$28,0) -> 22 | I13: =IFERROR(AVERAGEIFS(Cleaned_Procurement!$K$2:$K$1801,Cleaned_Procurement!$E$2:$E$1801,A13),0) -> 46.621622 | K13: 8 | L13: =INDEX($A$5:$A$28,MATCH(K13,$H$5:$H$28,0)) -> UK Energy Partners | M13: =INDEX($D$5:$D$28,MATCH(K13,$H$5:$H$28,0)) -> 833961.1 | N13: =IFERROR(M13/$D$29,0) -> 0.05990247 | O13: =SUM($N$6:N13) -> 0.55300946 | P13: =INDEX($C$5:$C$28,MATCH(K13,$H$5:$H$28,0)) -> N
A14: =Supplier_Lookup!A11 -> HealthStaffing | B14: =Supplier_Lookup!B11 -> Agency Labour | C14: =Supplier_Lookup!C11 -> N | D14: =SUMIFS(Cleaned_Procurement!$O$2:$O$1801,Cleaned_Procurement!$E$2:$E$1801,A14) -> 1072844.7 | E14: =COUNTIFS(Cleaned_Procurement!$E$2:$E$1801,A14) -> 85 | F14: =IFERROR(D14/E14,0) -> 12621.702 | G14: =IFERROR(D14/$D$29,0) -> 0.077061205 | H14: =RANK(D14,$D$5:$D$28,0) -> 2 | I14: =IFERROR(AVERAGEIFS(Cleaned_Procurement!$K$2:$K$1801,Cleaned_Procurement!$E$2:$E$1801,A14),0) -> 46.411765 | K14: 9 | L14: =INDEX($A$5:$A$28,MATCH(K14,$H$5:$H$28,0)) -> TeleCare IT | M14: =INDEX($D$5:$D$28,MATCH(K14,$H$5:$H$28,0)) -> 774305.94 | N14: =IFERROR(M14/$D$29,0) -> 0.055617508 | O14: =SUM($N$6:N14) -> 0.60862697 | P14: =INDEX($C$5:$C$28,MATCH(K14,$H$5:$H$28,0)) -> N
A15: =Supplier_Lookup!A12 -> KitchenPro | B15: =Supplier_Lookup!B12 -> Food & Catering | C15: =Supplier_Lookup!C12 -> N | D15: =SUMIFS(Cleaned_Procurement!$O$2:$O$1801,Cleaned_Procurement!$E$2:$E$1801,A15) -> 279264.56 | E15: =COUNTIFS(Cleaned_Procurement!$E$2:$E$1801,A15) -> 87 | F15: =IFERROR(D15/E15,0) -> 3209.9375 | G15: =IFERROR(D15/$D$29,0) -> 0.020059253 | H15: =RANK(D15,$D$5:$D$28,0) -> 21 | I15: =IFERROR(AVERAGEIFS(Cleaned_Procurement!$K$2:$K$1801,Cleaned_Procurement!$E$2:$E$1801,A15),0) -> 45.344828 | K15: 10 | L15: =INDEX($A$5:$A$28,MATCH(K15,$H$5:$H$28,0)) -> BuildCare | M15: =INDEX($D$5:$D$28,MATCH(K15,$H$5:$H$28,0)) -> 647209.95 | N15: =IFERROR(M15/$D$29,0) -> 0.046488349 | O15: =SUM($N$6:N15) -> 0.65511532 | P15: =INDEX($C$5:$C$28,MATCH(K15,$H$5:$H$28,0)) -> N
A16: =Supplier_Lookup!A13 -> LearnWell | B16: =Supplier_Lookup!B13 -> Office & Training | C16: =Supplier_Lookup!C13 -> N | D16: =SUMIFS(Cleaned_Procurement!$O$2:$O$1801,Cleaned_Procurement!$E$2:$E$1801,A16) -> 236027.71 | E16: =COUNTIFS(Cleaned_Procurement!$E$2:$E$1801,A16) -> 71 | F16: =IFERROR(D16/E16,0) -> 3324.3339 | G16: =IFERROR(D16/$D$29,0) -> 0.0169536 | H16: =RANK(D16,$D$5:$D$28,0) -> 23 | I16: =IFERROR(AVERAGEIFS(Cleaned_Procurement!$K$2:$K$1801,Cleaned_Procurement!$E$2:$E$1801,A16),0) -> 45.633803
A17: =Supplier_Lookup!A14 -> MediSure | B17: =Supplier_Lookup!B14 -> Medical Supplies | C17: =Supplier_Lookup!C14 -> Y | D17: =SUMIFS(Cleaned_Procurement!$O$2:$O$1801,Cleaned_Procurement!$E$2:$E$1801,A17) -> 423187.89 | E17: =COUNTIFS(Cleaned_Procurement!$E$2:$E$1801,A17) -> 75 | F17: =IFERROR(D17/E17,0) -> 5642.5052 | G17: =IFERROR(D17/$D$29,0) -> 0.030397101 | H17: =RANK(D17,$D$5:$D$28,0) -> 14 | I17: =IFERROR(AVERAGEIFS(Cleaned_Procurement!$K$2:$K$1801,Cleaned_Procurement!$E$2:$E$1801,A17),0) -> 46.4
A18: =Supplier_Lookup!A15 -> NetServe | B18: =Supplier_Lookup!B15 -> IT & Telecoms | C18: =Supplier_Lookup!C15 -> N | D18: =SUMIFS(Cleaned_Procurement!$O$2:$O$1801,Cleaned_Procurement!$E$2:$E$1801,A18) -> 851726.08 | E18: =COUNTIFS(Cleaned_Procurement!$E$2:$E$1801,A18) -> 86 | F18: =IFERROR(D18/E18,0) -> 9903.7916 | G18: =IFERROR(D18/$D$29,0) -> 0.061178508 | H18: =RANK(D18,$D$5:$D$28,0) -> 7 | I18: =IFERROR(AVERAGEIFS(Cleaned_Procurement!$K$2:$K$1801,Cleaned_Procurement!$E$2:$E$1801,A18),0) -> 47.790698 | K18: Findings (live)
A19: =Supplier_Lookup!A16 -> NourishCo | B19: =Supplier_Lookup!B16 -> Food & Catering | C19: =Supplier_Lookup!C16 -> N | D19: =SUMIFS(Cleaned_Procurement!$O$2:$O$1801,Cleaned_Procurement!$E$2:$E$1801,A19) -> 319833.4 | E19: =COUNTIFS(Cleaned_Procurement!$E$2:$E$1801,A19) -> 87 | F19: =IFERROR(D19/E19,0) -> 3676.246 | G19: =IFERROR(D19/$D$29,0) -> 0.022973267 | H19: =RANK(D19,$D$5:$D$28,0) -> 16 | I19: =IFERROR(AVERAGEIFS(Cleaned_Procurement!$K$2:$K$1801,Cleaned_Procurement!$E$2:$E$1801,A19),0) -> 42.586207 | K19: ="Top 5 suppliers account for "&TEXT(O10,"0%")&" of attributed spend; top 10 for "&TEXT(O15,"0%")&"." -> Top 5 suppliers account for 37% of attributed spend; top 10 for 66%.
A20: =Supplier_Lookup!A17 -> NurseLink | B20: =Supplier_Lookup!B17 -> Agency Labour | C20: =Supplier_Lookup!C17 -> N | D20: =SUMIFS(Cleaned_Procurement!$O$2:$O$1801,Cleaned_Procurement!$E$2:$E$1801,A20) -> 1161388.4 | E20: =COUNTIFS(Cleaned_Procurement!$E$2:$E$1801,A20) -> 84 | F20: =IFERROR(D20/E20,0) -> 13826.052 | G20: =IFERROR(D20/$D$29,0) -> 0.083421198 | H20: =RANK(D20,$D$5:$D$28,0) -> 1 | I20: =IFERROR(AVERAGEIFS(Cleaned_Procurement!$K$2:$K$1801,Cleaned_Procurement!$E$2:$E$1801,A20),0) -> 45.178571 | K20: ="Off-contract spend: "&TEXT(SUMIFS(Cleaned_Procurement!O2:O1801,Cleaned_Procurement!M2:M1801,"N"),"£#,##0")&" ("&TEXT(SUMIFS(Cleaned_Procurement!O2:O1801,Cleaned_Procurement!M2:M1801,"N")/SUM(Cleaned_Procurement!O2:O1801),"0%")&" of total), the main lever for the savings plan." -> Off-contract spend: £11,473,793 (82% of total), the main lever for the savings plan.
A21: =Supplier_Lookup!A18 -> OfficePlus | B21: =Supplier_Lookup!B18 -> Office & Training | C21: =Supplier_Lookup!C18 -> N | D21: =SUMIFS(Cleaned_Procurement!$O$2:$O$1801,Cleaned_Procurement!$E$2:$E$1801,A21) -> 294325.78 | E21: =COUNTIFS(Cleaned_Procurement!$E$2:$E$1801,A21) -> 82 | F21: =IFERROR(D21/E21,0) -> 3589.3388 | G21: =IFERROR(D21/$D$29,0) -> 0.021141083 | H21: =RANK(D21,$D$5:$D$28,0) -> 19 | I21: =IFERROR(AVERAGEIFS(Cleaned_Procurement!$K$2:$K$1801,Cleaned_Procurement!$E$2:$E$1801,A21),0) -> 46.280488 | K21: ="Largest single supplier: "&L6&" at "&TEXT(M6,"£#,##0")&IF(P6="N",", not under contract.",", under contract.") -> Largest single supplier: NurseLink at £1,161,388, not under contract.
A22: =Supplier_Lookup!A19 -> PowerDirect | B22: =Supplier_Lookup!B19 -> Utilities | C22: =Supplier_Lookup!C19 -> N | D22: =SUMIFS(Cleaned_Procurement!$O$2:$O$1801,Cleaned_Procurement!$E$2:$E$1801,A22) -> 1048249.1 | E22: =COUNTIFS(Cleaned_Procurement!$E$2:$E$1801,A22) -> 87 | F22: =IFERROR(D22/E22,0) -> 12048.84 | G22: =IFERROR(D22/$D$29,0) -> 0.075294533 | H22: =RANK(D22,$D$5:$D$28,0) -> 3 | I22: =IFERROR(AVERAGEIFS(Cleaned_Procurement!$K$2:$K$1801,Cleaned_Procurement!$E$2:$E$1801,A22),0) -> 44.482759
A23: =Supplier_Lookup!A20 -> PrintCo | B23: =Supplier_Lookup!B20 -> Office & Training | C23: =Supplier_Lookup!C20 -> N | D23: =SUMIFS(Cleaned_Procurement!$O$2:$O$1801,Cleaned_Procurement!$E$2:$E$1801,A23) -> 197576.58 | E23: =COUNTIFS(Cleaned_Procurement!$E$2:$E$1801,A23) -> 68 | F23: =IFERROR(D23/E23,0) -> 2905.5379 | G23: =IFERROR(D23/$D$29,0) -> 0.014191699 | H23: =RANK(D23,$D$5:$D$28,0) -> 24 | I23: =IFERROR(AVERAGEIFS(Cleaned_Procurement!$K$2:$K$1801,Cleaned_Procurement!$E$2:$E$1801,A23),0) -> 44.117647
A24: =Supplier_Lookup!A21 -> RoadReady | B24: =Supplier_Lookup!B21 -> Vehicle & Fuel | C24: =Supplier_Lookup!C21 -> N | D24: =SUMIFS(Cleaned_Procurement!$O$2:$O$1801,Cleaned_Procurement!$E$2:$E$1801,A24) -> 432111.81 | E24: =COUNTIFS(Cleaned_Procurement!$E$2:$E$1801,A24) -> 90 | F24: =IFERROR(D24/E24,0) -> 4801.2423 | G24: =IFERROR(D24/$D$29,0) -> 0.031038096 | H24: =RANK(D24,$D$5:$D$28,0) -> 13 | I24: =IFERROR(AVERAGEIFS(Cleaned_Procurement!$K$2:$K$1801,Cleaned_Procurement!$E$2:$E$1801,A24),0) -> 44.5
A25: =Supplier_Lookup!A22 -> SafeGuard FM | B25: =Supplier_Lookup!B22 -> Facilities | C25: =Supplier_Lookup!C22 -> N | D25: =SUMIFS(Cleaned_Procurement!$O$2:$O$1801,Cleaned_Procurement!$E$2:$E$1801,A25) -> 890207.06 | E25: =COUNTIFS(Cleaned_Procurement!$E$2:$E$1801,A25) -> 76 | F25: =IFERROR(D25/E25,0) -> 11713.251 | G25: =IFERROR(D25/$D$29,0) -> 0.063942553 | H25: =RANK(D25,$D$5:$D$28,0) -> 5 | I25: =IFERROR(AVERAGEIFS(Cleaned_Procurement!$K$2:$K$1801,Cleaned_Procurement!$E$2:$E$1801,A25),0) -> 44.802632
