Workbook

Sheet README
B2: Advanced Excel & Financial Modelling Project
B5: Purpose | C5: Portfolio project simulating a Commercial Data Analyst environment covering procurement, fleet, workforce, agency and finance.
B6: Data | C6: Synthetic data created for this project. It contains intentionally messy records to demonstrate cleansing and validation. No real CareTech data is used.
B7: Advanced Excel skills | C7: Excel Tables, structured references, VLOOKUP/XLOOKUP-style lookups, INDEX/MATCH, SUMIFS, COUNTIFS, IFERROR, conditional formatting, data validation, charts, pivot-style analysis, scenario modelling and financial KPIs.
B8: VBA | C8: Separate .bas scripts automate cleansing, duplicate detection, CSV consolidation and dashboard refresh. Import them into the VBA editor (Alt+F11) in a macro-enabled copy of the workbook.
B9: Financial model | C9: Driver-based 2026 forecast with Base/Conservative/Aggressive scenarios, savings assumptions, budget-vs-forecast analysis and EBITDA impact.
B10: GDPR | C10: The data is synthetic and contains no service-user, employee or supplier personal data. The project demonstrates a GDPR-first approach by using IDs and aggregated commercial measures.
B11: How to use | C11: 1) Review Dashboard. 2) Change Scenario in Financial_Model!B4. 3) Review Savings_Tracker. 4) Inspect Pivot_Analysis. 5) Review Formula_Audit and VBA_Code. 6) Import the supplied .bas files into Excel to test automation.
B12: Portfolio story | C12: The analyst receives fragmented source files, cleans and validates them, consolidates commercial measures, identifies spend drivers and exceptions, models savings scenarios, and communicates the financial impact through an executive dashboard.

Sheet Procurement_Raw
A1: InvoiceDate | B1: SiteID | C1: SiteName | D1: Region | E1: Supplier | F1: Category | G1: InvoiceID | H1: Quantity | I1: UnitCost | J1: GrossSpend | K1: PaymentTermsDays | L1: SourceSystem | M1: VAT | N1: NetSpend | O1: Contracted | P1: DataQualityFlag
A2: 45798 | B2: S006 | C2: Birmingham Care & Education Centre | D2: Midlands | E2: freshserve | F2: Food & Catering | G2: INV-2025-00001 | H2: 32 | I2: 85.42 | J2: 2733.44 | K2: 30 | L2: ERP | M2: 546.688 | N2: 2733.44 | O2: Y | P2: OK
A3: 45937 | B3: S008 | C3: Leicester Care & Education Centre | D3: Midlands | E3: KitchenPro | F3: Food & Catering | G3: INV-2025-00002 | H3: 12 | I3: 60.24 | J3: 722.88 | K3: 60 | L3: Procurement Portal | M3: 144.576 | N3: 722.88 | O3: N | P3: OK
A4: 45769 | B4: S009 | C4: Derby Care & Education Centre | D4: Midlands | E4: MediSure | F4: Medical Supplies | G4: INV-2025-00003 | H4: 30 | I4: 171.35 | J4: 5140.56 | K4: 60 | L4: Legacy Spend File | M4: 1028.112 | N4: 5140.56 | O4: Y | P4: OK
A5: 45990 | B5: S006 | C5: Birmingham Care & Education Centre | D5: Midlands | E5: PowerDirect | F5: Utilities | G5: INV-2025-00004 | H5: 70 | I5: 577.74 | J5: 40441.94 | K5: 45 | L5: ERP | M5: 8088.388 | N5: 40441.94 | O5: N | P5: OK
A6: 45739 | B6: S016 | C6: Cardiff Care & Education Centre | D6: Wales | E6: CloudLink | F6: IT & Telecoms | G6: INV-2025-00005 | H6: 55 | I6: 193.42 | J6: 10637.88 | K6: 45 | L6: Procurement Portal | M6: 2127.576 | N6: 10637.88 | O6: Y | P6: OK
A7: 45710 | B7: S013 | C7: Reading Care & Education Centre | D7: South | E7: WaterGrid | F7: Utilities | G7: INV-2025-00006 | H7: 12 | I7: 219.79 | J7: 2637.51 | K7: 45 | L7: ERP | M7: 527.502 | N7: 2637.51 | O7: N | P7: OK
A8: 45793 | B8: S005 | C8: Sheffield Care & Education Centre | D8: North | E8: AutoCare | F8: Vehicle & Fuel | G8: INV-2025-00007 | H8: 6 | I8: 226.43 | J8: 1358.59 | K8: 60 | L8: Procurement Portal | M8: 271.718 | N8: 1358.59 | O8: N | P8: OK
A9: 45698 | B9: S004 | C9: Newcastle Care & Education Centre | D9: North | E9: NourishCo | F9: Food & Catering | G9: INV-2025-00008 | H9: 71 | I9: 99.13 | J9: 7038.54 | K9: 45 | L9: Legacy Spend File | M9: 1407.708 | N9: 7038.54 | O9: N | P9: OK
A10: 45756 | B10: S017 | C10: Swansea Care & Education Centre | D10: Wales | E10: AutoCare | F10: Vehicle & Fuel | G10: INV-2025-00009 | H10: 9 | I10: 73.38 | J10: 660.43 | K10: 30 | L10: Legacy Spend File | M10: 132.086 | N10: 660.43 | O10: N | P10: OK
A11: 45777 | B11: S015 | C11: Brighton Care & Education Centre | D11: South | E11: CloudLink | F11: IT & Telecoms | G11: INV-2025-00010 | H11: 13 | I11: 296.5 | J11: 3854.46 | K11: 45 | L11: Procurement Portal | M11: 770.892 | N11: 3854.46 | O11: Y | P11: OK
A12: 45847 | B12: S016 | C12: Cardiff Care & Education Centre | D12: Wales | E12: FleetFuel | F12: Vehicle & Fuel | G12: INV-2025-00011 | H12: 46 | I12: 73.63 | J12: 3386.79 | K12: 30 | L12: Legacy Spend File | M12: 677.358 | N12: 3386.79 | O12: Y | P12: OK
A13: 45983 | B13: S019 | C13: Wrexham Care & Education Centre | D13: Wales | E13: KitchenPro | F13: Food & Catering | G13: INV-2025-00012 | H13: 22 | I13: 50.31 | J13: 1106.86 | K13: 60 | L13: Legacy Spend File | M13: 221.372 | N13: 1106.86 | O13: N | P13: OK
... A78: 45884 | B78: S014 | C78: Southampton Care & Education Centre | D78: South | E78: RoadReady | F78: Vehicle & Fuel | G78: INV-2025-00077 | H78: 57 | I78: 99.66 | J78: 5680.55 | K78: 60 | L78: ERP | M78: 1136.11 | N78: 5680.55 | O78: N | P78: OK
A79: 45744 | B79: S005 | C79: Sheffield Care & Education Centre | D79: North | F79: Office & Training | G79: INV-2025-00078 | H79: 11 | I79: 63.63 | J79: 699.89 | K79: 45 | L79: Legacy Spend File | M79: 139.978 | N79: 699.89 | O79: N | P79: Missing supplier
A80: 45778 | B80: S020 | C80: Bangor Care & Education Centre | D80: Wales | E80: FleetFuel | F80: Vehicle & Fuel | G80: INV-2025-00079 | H80: 40 | I80: 99.92 | J80: 3996.7 | K80: 30 | L80: ERP | M80: 799.34 | N80: 3996.7 | O80: Y | P80: OK
A81: 45783 | B81: S017 | C81: Swansea Care & Education Centre | D81: Wales | E81: MediSure | F81: Medical Supplies | G81: INV-2025-00080 | H81: 61 | I81: 40.22 | J81: 2453.33 | K81: 60 | L81: ERP | M81: 490.666 | N81: 2453.33 | O81: Y | P81: OK
A82: 45952 | B82: S008 | C82: Leicester Care & Education Centre | D82: Midlands | E82: NurseLink | F82: Agency Labour | G82: INV-2025-00081 | H82: 25 | I82: 265.86 | J82: 6646.45 | K82: 60 | L82: Legacy Spend File | M82: 1329.29 | N82: 6646.45 | O82: N | P82: OK
A83: 45782 | B83: S019 | C83: Wrexham Care & Education Centre | D83: Wales | E83: LearnWell | F83: Office & Training | G83: INV-2025-00082 | H83: 19 | I83: 91.28 | J83: 1734.27 | K83: 60 | L83: Legacy Spend File | M83: 346.854 | N83: 1734.27 | O83: N | P83: OK
A84: 45770 | B84: S008 | C84: Leicester Care & Education Centre | D84: Midlands | E84: NourishCo | F84: Food & Catering | G84: INV-2025-00083 | H84: 23 | I84: 146.53 | J84: 3370.19 | K84: 60 | L84: Legacy Spend File | M84: 674.038 | N84: 3370.19 | O84: N | P84: OK
A85: 45785 | B85: S014 | C85: Southampton Care & Education Centre | D85: South | E85: ClinEquip | F85: Medical Supplies | G85: INV-2025-00084 | H85: 16 | I85: 90.24 | J85: 1443.8 | K85: 45 | L85: ERP | M85: 288.76 | N85: 1443.8 | O85: N | P85: OK
A86: 45971 | B86: S012 | C86: Bristol Care & Education Centre | D86: South | E86: RoadReady | F86: Vehicle & Fuel | G86: INV-2025-00085 | H86: 65 | I86: 60.9 | J86: 3958.39 | K86: 45 | L86: Legacy Spend File | M86: 791.678 | N86: 3958.39 | O86: N | P86: OK
A87: 45901 | B87: S008 | C87: Leicester Care & Education Centre | D87: Midlands | E87: BuildCare | F87: Facilities | G87: INV-2025-00086 | H87: 58 | I87: 136.59 | J87: 7922.27 | K87: 45 | L87: ERP | M87: 1584.454 | N87: 7922.27 | O87: N | P87: OK
A88: 45906 | B88: S007 | C88: Nottingham Care & Education Centre | D88: Midlands | E88: NetServe | F88: IT & Telecoms | G88: INV-2025-00087 | H88: 31 | I88: 363.98 | J88: 11283.38 | K88: 45 | L88: Procurement Portal | M88: 2256.676 | N88: 11283.38 | O88: N | P88: OK
A89: 45797 | B89: S005 | C89: Sheffield Care & Education Centre | D89: North | E89: CloudLink | F89: IT & Telecoms | G89: INV-2025-00088 | H89: 43 | I89: 263.6 | J89: 11334.89 | K89: 45 | L89: Legacy Spend File | M89: 2266.978 | N89: 11334.89 | O89: Y | P89: OK
A90: 45776 | B90: S007 | C90: Nottingham Care & Education Centre | D90: Midlands | E90: CleanWorks | F90: Facilities | G90: INV-2025-00089 | H90: 50 | I90: 134.5 | J90: 6725.17 | K90: 60 | L90: ERP | M90: 1345.034 | N90: 6725.17 | O90: Y | P90: OK
A91: 45870 | B91: S011 | C91: London Care & Education Centre | D91: South | E91: UK Energy Partners | F91: Utilities | G91: INV-2025-00090 | H91: 53 | I91: 331.54 | J91: 17571.79 | K91: 45 | L91: Legacy Spend File | M91: 3514.358 | N91: 17571.79 | O91: N | P91: OK
... A902: 45879 | B902: S009 | C902: Derby Care & Education Centre | D902: Midlands | E902: FreshServe | F902: Food & Catering | G902: INV-2025-00901 | H902: 38 | I902: 79.61 | J902: 3025.23 | K902: 45 | L902: ERP | M902: 605.046 | N902: 3025.23 | O902: Y | P902: OK
A903: 45901 | C903: Preston Care & Education Centre | D903: North | E903: FleetFuel | F903: Vehicle & Fuel | G903: INV-2025-00902 | H903: 74 | I903: 76.52 | J903: 5662.41 | K903: 60 | L903: ERP | M903: 1132.482 | N903: 5662.41 | O903: Y | P903: Missing site
A904: 45701 | B904: S005 | C904: Sheffield Care & Education Centre | D904: North | E904: CareTemps | F904: Agency Labour | G904: INV-2025-00903 | H904: 52 | I904: 304.78 | J904: 15848.59 | K904: 60 | L904: Procurement Portal | M904: 3169.718 | N904: 15848.59 | O904: N | P904: OK
A905: 45904 | B905: S016 | C905: Cardiff Care & Education Centre | D905: Wales | E905: CleanWorks | F905: Facilities | G905: INV-2025-00904 | H905: 72 | I905: 363.62 | J905: 26180.54 | K905: 30 | L905: Procurement Portal | M905: 5236.108 | N905: 26180.54 | O905: Y | P905: OK
A906: 45973 | B906: S009 | C906: Derby Care & Education Centre | D906: Midlands | E906: PowerDirect | F906: Utilities | G906: INV-2025-00905 | H906: 68 | I906: 277.71 | J906: 18884.05 | K906: 30 | L906: ERP | M906: 3776.81 | N906: 18884.05 | O906: N | P906: OK
A907: 45823 | B907: S011 | C907: London Care & Education Centre | D907: South | E907: TeleCare IT | F907: IT & Telecoms | G907: INV-2025-00906 | H907: 74 | I907: 225.69 | J907: 16701.15 | K907: 30 | L907: ERP | M907: 3340.23 | N907: 16701.15 | O907: N | P907: OK
A908: 45845 | B908: S010 | C908: Coventry Care & Education Centre | D908: Midlands | E908: CareTemps | F908: Agency Labour | G908: INV-2025-00907 | H908: 45 | I908: 142 | J908: 6390.22 | K908: 30 | L908: Procurement Portal | M908: 1278.044 | N908: 6390.22 | O908: N | P908: OK
A909: 45744 | B909: S008 | C909: Leicester Care & Education Centre | D909: Midlands | E909: CareMed | F909: Medical Supplies | G909: INV-2025-00908 | H909: 45 | I909: 180.9 | J909: 8140.39 | K909: 60 | L909: Procurement Portal | M909: 1628.078 | N909: 8140.39 | O909: N | P909: OK
A910: 45680 | B910: S016 | C910: Cardiff Care & Education Centre | D910: Wales | E910: SafeGuard FM | F910: Facilities | G910: INV-2025-00909 | H910: 30 | I910: 256.72 | J910: 7701.5 | K910: 30 | L910: Legacy Spend File | M910: 1540.3 | N910: 7701.5 | O910: N | P910: OK
A911: 45701 | B911: S001 | C911: Preston Care & Education Centre | D911: North | E911: BuildCare | F911: Facilities | G911: INV-2025-00910 | H911: 15 | I911: 591.55 | J911: 8873.26 | K911: 60 | L911: ERP | M911: 1774.652 | N911: 8873.26 | O911: N | P911: OK
A912: 45665 | B912: S015 | C912: Brighton Care & Education Centre | D912: South | E912: SafeGuard FM | F912: Facilities | G912: INV-2025-00911 | H912: 44 | I912: 151.97 | J912: 6686.65 | K912: 60 | L912: ERP | M912: 1337.33 | N912: 6686.65 | O912: N | P912: OK
A913: 45669 | B913: S019 | C913: Wrexham Care & Education Centre | D913: Wales | E913: LearnWell | F913: Office & Training | G913: INV-2025-00912 | H913: 43 | I913: 84.61 | J913: 3638.11 | K913: 30 | L913: Legacy Spend File | M913: 727.622 | N913: 3638.11 | O913: N | P913: OK
A914: 45937 | B914: S015 | C914: Brighton Care & Education Centre | D914: South | E914: UK Energy Partners | F914: Utilities | G914: INV-2025-00913 | H914: 67 | I914: 286.75 | J914: 19212.46 | K914: 45 | L914: Legacy Spend File | M914: 3842.492 | N914: 19212.46 | O914: N | P914: OK
...

Sheet Fleet_Raw
A1: Month | B1: SiteID | C1: SiteName | D1: Region | E1: VehicleID | F1: VehicleType | G1: Miles | H1: FuelLitres | I1: FuelCost | J1: MaintenanceCost | K1: LeaseCost | L1: TotalFleetCost
A2: 45658 | B2: S001 | C2: Preston Care & Education Centre | D2: North | E2: VH0077 | F2: Van | G2: 1525 | H2: 179.4 | I2: 265.51 | J2: 145.15 | K2: 450 | L2: 860.66
A3: 45658 | B3: S001 | C3: Preston Care & Education Centre | D3: North | E3: VH0050 | F3: Car | G3: 872 | H3: 83 | I3: 122.84 | J3: 28.9 | K3: 450 | L3: 601.74
A4: 45658 | B4: S001 | C4: Preston Care & Education Centre | D4: North | E4: VH0138 | F4: Car | G4: 599 | H4: 57 | I4: 84.36 | J4: 23.27 | K4: 380 | L4: 487.63
A5: 45658 | B5: S001 | C5: Preston Care & Education Centre | D5: North | E5: VH0063 | F5: Car | G5: 1116 | H5: 106.3 | I5: 157.32 | J5: 190.7 | K5: 320 | L5: 668.02
A6: 45658 | B6: S002 | C6: Manchester Care & Education Centre | D6: North | E6: VH0118 | F6: MPV | G6: 654 | H6: 62.3 | I6: 92.2 | J6: 221.6 | K6: 450 | L6: 763.8
A7: 45658 | B7: S002 | C7: Manchester Care & Education Centre | D7: North | E7: VH0032 | F7: Minibus | G7: 929 | H7: 109.3 | I7: 161.76 | J7: 261.74 | K7: 380 | L7: 803.5
A8: 45658 | B8: S002 | C8: Manchester Care & Education Centre | D8: North | E8: VH0028 | F8: Car | G8: 1453 | H8: 138.4 | I8: 204.83 | J8: 221.75 | K8: 320 | L8: 746.58
A9: 45658 | B9: S003 | C9: Leeds Care & Education Centre | D9: North | E9: VH0093 | F9: Van | G9: 982 | H9: 115.5 | I9: 170.94 | J9: 78.7 | K9: 320 | L9: 569.64
A10: 45658 | B10: S003 | C10: Leeds Care & Education Centre | D10: North | E10: VH0054 | F10: Van | G10: 512 | H10: 60.2 | I10: 89.1 | J10: 92.47 | K10: 320 | L10: 501.57
A11: 45658 | B11: S003 | C11: Leeds Care & Education Centre | D11: North | E11: VH0101 | F11: MPV | G11: 997 | H11: 95 | I11: 140.6 | J11: 71.03 | K11: 520 | L11: 731.63
A12: 45658 | B12: S003 | C12: Leeds Care & Education Centre | D12: North | E12: VH0026 | F12: Van | G12: 1017 | H12: 119.6 | I12: 177.01 | J12: 156.15 | K12: 450 | L12: 783.16
A13: 45658 | B13: S003 | C13: Leeds Care & Education Centre | D13: North | E13: VH0126 | F13: Van | G13: 993 | H13: 116.8 | I13: 172.86 | J13: 98 | K13: 380 | L13: 650.86
... A1160: 45992 | B1160: S020 | C1160: Bangor Care & Education Centre | D1160: Wales | E1160: VH0056 | F1160: Minibus | G1160: 989 | H1160: 116.4 | I1160: 172.27 | J1160: 98.8 | K1160: 520 | L1160: 791.07

Sheet Workforce_Raw
A1: Month | B1: SiteID | C1: SiteName | D1: Region | E1: Role | F1: FTE | G1: AnnualSalary | H1: OvertimeHours | I1: OvertimeCost | J1: AbsenceDays | K1: BasePayroll | L1: TotalPayroll
A2: 45658 | B2: S001 | C2: Preston Care & Education Centre | D2: North | E2: Support Worker | F2: 16.7 | G2: 25000 | H2: 55.4 | I2: 887.82 | J2: 7.3 | K2: 34791.667 | L2: 35679.487
A3: 45658 | B3: S001 | C3: Preston Care & Education Centre | D3: North | E3: Manager | F3: 17.7 | G3: 43000 | H3: 54.7 | I3: 1507.76 | J3: 8.7 | K3: 63425 | L3: 64932.76
A4: 45658 | B4: S001 | C4: Preston Care & Education Centre | D4: North | E4: Senior Support Worker | F4: 9.3 | G4: 29000 | H4: 50.6 | I4: 940.64 | J4: 4.9 | K4: 22475 | L4: 23415.64
A5: 45658 | B5: S001 | C5: Preston Care & Education Centre | D5: North | E5: Registered Nurse | F5: 19.5 | G5: 41000 | H5: 87 | I5: 2286.54 | J5: 8.7 | K5: 66625 | L5: 68911.54
A6: 45658 | B6: S001 | C6: Preston Care & Education Centre | D6: North | E6: Administrator | F6: 4.1 | G6: 27000 | H6: 11 | I6: 190.38 | J6: 3.8 | K6: 9225 | L6: 9415.38
A7: 45658 | B7: S001 | C7: Preston Care & Education Centre | D7: North | E7: Team Leader | F7: 10.6 | G7: 35000 | H7: 30.7 | I7: 688.78 | J7: 7 | K7: 30916.667 | L7: 31605.447
A8: 45658 | B8: S002 | C8: Manchester Care & Education Centre | D8: North | E8: Senior Support Worker | F8: 13.8 | G8: 29000 | H8: 50.2 | I8: 933.21 | J8: 6.9 | K8: 33350 | L8: 34283.21
A9: 45658 | B9: S002 | C9: Manchester Care & Education Centre | D9: North | E9: Driver | F9: 18.3 | G9: 28000 | H9: 102.6 | I9: 1841.54 | J9: 10.4 | K9: 42700 | L9: 44541.54
A10: 45658 | B10: S002 | C10: Manchester Care & Education Centre | D10: North | E10: Registered Nurse | F10: 11.1 | G10: 41000 | H10: 42.6 | I10: 1119.62 | J10: 5.2 | K10: 37925 | L10: 39044.62
A11: 45658 | B11: S002 | C11: Manchester Care & Education Centre | D11: North | E11: Administrator | F11: 7.8 | G11: 27000 | H11: 30.5 | I11: 527.88 | J11: 4.2 | K11: 17550 | L11: 18077.88
A12: 45658 | B12: S002 | C12: Manchester Care & Education Centre | D12: North | E12: Team Leader | F12: 8.8 | G12: 35000 | H12: 47 | I12: 1054.49 | J12: 4.4 | K12: 25666.667 | L12: 26721.157
A13: 45658 | B13: S003 | C13: Leeds Care & Education Centre | D13: North | E13: Administrator | F13: 12.7 | G13: 27000 | H13: 62.6 | I13: 1083.46 | J13: 8 | K13: 28575 | L13: 29658.46
... A1194: 45992 | B1194: S020 | C1194: Bangor Care & Education Centre | D1194: Wales | E1194: Administrator | F1194: 13.3 | G1194: 27000 | H1194: 61.9 | I1194: 1071.35 | J1194: 5.3 | K1194: 29925 | L1194: 30996.35

Sheet Agency_Raw
A1: Month | B1: SiteID | C1: SiteName | D1: Region | E1: Agency | F1: Role | G1: Hours | H1: HourlyRate | I1: AgencySpend
A2: 45658 | B2: S001 | C2: Preston Care & Education Centre | D2: North | E2: CareTemps | F2: Registered Nurse | G2: 127 | H2: 42 | I2: 5334
A3: 45658 | B3: S001 | C3: Preston Care & Education Centre | D3: North | E3: HealthStaffing | F3: Support Worker | G3: 80 | H3: 23 | I3: 1840
A4: 45658 | B4: S001 | C4: Preston Care & Education Centre | D4: North | E4: NurseLink | F4: Senior Support Worker | G4: 134 | H4: 28 | I4: 3752
A5: 45658 | B5: S002 | C5: Manchester Care & Education Centre | D5: North | E5: NurseLink | F5: Support Worker | G5: 107 | H5: 23 | I5: 2461
A6: 45658 | B6: S002 | C6: Manchester Care & Education Centre | D6: North | E6: HealthStaffing | F6: Registered Nurse | G6: 47 | H6: 42 | I6: 1974
A7: 45658 | B7: S002 | C7: Manchester Care & Education Centre | D7: North | E7: HealthStaffing | F7: Senior Support Worker | G7: 139 | H7: 28 | I7: 3892
A8: 45658 | B8: S003 | C8: Leeds Care & Education Centre | D8: North | E8: CareTemps | F8: Registered Nurse | G8: 144 | H8: 42 | I8: 6048
A9: 45658 | B9: S003 | C9: Leeds Care & Education Centre | D9: North | E9: HealthStaffing | F9: Support Worker | G9: 120 | H9: 23 | I9: 2760
A10: 45658 | B10: S003 | C10: Leeds Care & Education Centre | D10: North | E10: CareTemps | F10: Senior Support Worker | G10: 63 | H10: 28 | I10: 1764
A11: 45658 | B11: S004 | C11: Newcastle Care & Education Centre | D11: North | E11: CareTemps | F11: Registered Nurse | G11: 79 | H11: 42 | I11: 3318
A12: 45658 | B12: S004 | C12: Newcastle Care & Education Centre | D12: North | E12: HealthStaffing | F12: Senior Support Worker | G12: 95 | H12: 28 | I12: 2660
A13: 45658 | B13: S005 | C13: Sheffield Care & Education Centre | D13: North | E13: CareTemps | F13: Senior Support Worker | G13: 65 | H13: 28 | I13: 1820
... A493: 45992 | B493: S020 | C493: Bangor Care & Education Centre | D493: Wales | E493: CareTemps | F493: Senior Support Worker | G493: 79 | H493: 28 | I493: 2212

Sheet Finance_Raw
A1: Month | B1: SiteID | C1: SiteName | D1: Region | E1: Revenue | F1: Payroll | G1: Procurement | H1: Fleet | I1: Agency | J1: OtherOpex | K1: BudgetOpex | L1: ActualOpex | M1: EBITDA | N1: EBITDA_Margin
A2: 45658 | B2: S001 | C2: Preston Care & Education Centre | D2: North | E2: 474619.09 | F2: 233960.25 | G2: 29957.93 | H2: 2618.05 | I2: 10926 | J2: 35029.32 | K2: 300615.21 | L2: 312491.55 | M2: 162127.54 | N2: 0.34159506
A3: 45658 | B3: S002 | C3: Manchester Care & Education Centre | D3: North | E3: 322229.82 | F3: 162668.41 | G3: 46147.12 | H3: 2313.88 | I3: 8327 | J3: 18848.64 | K3: 237293.33 | L3: 238305.05 | M3: 83924.773 | N3: 0.26045005
A4: 45658 | B4: S003 | C4: Leeds Care & Education Centre | D4: North | E4: 443270.86 | F4: 209015.65 | G4: 56737.51 | H4: 4026.14 | I4: 10572 | J4: 30594.89 | K4: 321242.97 | L4: 310946.19 | M4: 132324.67 | N4: 0.29851877
A5: 45658 | B5: S004 | C5: Newcastle Care & Education Centre | D5: North | E5: 225588.97 | F5: 126464.86 | G5: 19671.36 | H5: 2389.81 | I5: 5978 | J5: 17476.53 | K5: 168715.6 | L5: 171980.56 | M5: 53608.407 | N5: 0.23763753
A6: 45658 | B6: S005 | C6: Sheffield Care & Education Centre | D6: North | E6: 480577.57 | F6: 198889.36 | G6: 114638.36 | H6: 2136.15 | I6: 1820 | J6: 37508.21 | K6: 356469.83 | L6: 354992.08 | M6: 125585.49 | N6: 0.26132199
A7: 45658 | B7: S006 | C7: Birmingham Care & Education Centre | D7: Midlands | E7: 253082.63 | F7: 105935.07 | G7: 39216.38 | H7: 2082.71 | I7: 4172 | J7: 18193.51 | K7: 172312.36 | L7: 169599.67 | M7: 83482.963 | N7: 0.32986445
A8: 45658 | B8: S007 | C8: Nottingham Care & Education Centre | D8: Midlands | E8: 459390.76 | F8: 194379.62 | G8: 80306.32 | H8: 2365.07 | I8: 2890 | J8: 34864.61 | K8: 316673.53 | L8: 314805.62 | M8: 144585.14 | N8: 0.31473236
A9: 45658 | B9: S008 | C9: Leicester Care & Education Centre | D9: Midlands | E9: 408256.15 | F9: 187881.8 | G9: 70155.57 | H9: 3437.69 | I9: 4479 | J9: 30631.99 | K9: 301514.81 | L9: 296586.05 | M9: 111670.1 | N9: 0.2735295
A10: 45658 | B10: S009 | C10: Derby Care & Education Centre | D10: Midlands | E10: 257222.08 | F10: 107740.26 | G10: 46215.75 | H10: 5176.84 | I10: 8384 | J10: 15475.41 | K10: 179413.25 | L10: 182992.26 | M10: 74229.823 | N10: 0.28858263
A11: 45658 | B11: S010 | C11: Coventry Care & Education Centre | D11: Midlands | E11: 336788.75 | F11: 171773.51 | G11: 23581.27 | H11: 4097.03 | I11: 9165 | J11: 18906.29 | K11: 229154.82 | L11: 227523.1 | M11: 109265.65 | N11: 0.32443378
A12: 45658 | B12: S011 | C12: London Care & Education Centre | D12: South | E12: 275996.19 | F12: 107439.8 | G12: 49352.19 | H12: 5448.97 | I12: 7647 | J12: 20130.61 | K12: 189971.53 | L12: 190018.57 | M12: 85977.62 | N12: 0.31151742
A13: 45658 | B13: S012 | C13: Bristol Care & Education Centre | D13: South | E13: 323384.21 | F13: 148083.27 | G13: 34609.06 | H13: 2439.87 | I13: 5498 | J13: 25385.59 | K13: 216520.19 | L13: 216015.79 | M13: 107368.42 | N13: 0.33201505
... A241: 45992 | B241: S020 | C241: Bangor Care & Education Centre | D241: Wales | E241: 308061.88 | F241: 102978.73 | G241: 86456.91 | H241: 3087.47 | I241: 5026 | J241: 20533.07 | K241: 217368.84 | L241: 218082.18 | M241: 89979.703 | N241: 0.29208321

Sheet Sites
A1: SiteID | B1: SiteName | C1: Region | D1: Town
A2: S001 | B2: Preston Care & Education Centre | C2: North | D2: Preston
A3: S002 | B3: Manchester Care & Education Centre | C3: North | D3: Manchester
A4: S003 | B4: Leeds Care & Education Centre | C4: North | D4: Leeds
A5: S004 | B5: Newcastle Care & Education Centre | C5: North | D5: Newcastle
A6: S005 | B6: Sheffield Care & Education Centre | C6: North | D6: Sheffield
A7: S006 | B7: Birmingham Care & Education Centre | C7: Midlands | D7: Birmingham
A8: S007 | B8: Nottingham Care & Education Centre | C8: Midlands | D8: Nottingham
A9: S008 | B9: Leicester Care & Education Centre | C9: Midlands | D9: Leicester
A10: S009 | B10: Derby Care & Education Centre | C10: Midlands | D10: Derby
A11: S010 | B11: Coventry Care & Education Centre | C11: Midlands | D11: Coventry
A12: S011 | B12: London Care & Education Centre | C12: South | D12: London
... A21: S020 | B21: Bangor Care & Education Centre | C21: Wales | D21: Bangor

Sheet Category_Targets
A1: Category | B1: TargetSavingsPct | C1: Owner
A2: Medical Supplies | B2: 0.06 | C2: Procurement
A3: Food & Catering | B3: 0.04 | C3: Procurement
A4: Facilities | B4: 0.05 | C4: Facilities
A5: Utilities | B5: 0.03 | C5: Procurement
A6: IT & Telecoms | B6: 0.08 | C6: IT
A7: Vehicle & Fuel | B7: 0.05 | C7: Fleet
A8: Agency Labour | B8: 0.07 | C8: Workforce
A9: Office & Training | B9: 0.04 | C9: Commercial

Sheet Supplier_Lookup
A1: Supplier | B1: Category | C1: Contracted
A2: AutoCare | B2: Vehicle & Fuel | C2: N
A3: BuildCare | B3: Facilities | C3: N
A4: CareMed | B4: Medical Supplies | C4: N
A5: CareTemps | B5: Agency Labour | C5: N
A6: CleanWorks | B6: Facilities | C6: Y
A7: ClinEquip | B7: Medical Supplies | C7: N
A8: CloudLink | B8: medical supplies | C8: Y
A9: CloudLink | B9: IT & Telecoms | C9: Y
A10: FleetFuel | B10: Vehicle & Fuel | C10: Y
A11: FreshServe | B11: Food & Catering | C11: Y
A12: HealthStaffing | B12: Agency Labour | C12: N
... A38: uk energy partners | B38: Utilities | C38: N

Sheet Cleaned_Procurement
A1: InvoiceDate | B1: SiteID | C1: SiteName | D1: Region | E1: Supplier | F1: Category | G1: InvoiceID | H1: Quantity | I1: UnitCost | J1: GrossSpend | K1: PaymentTermsDays | L1: SourceSystem | M1: Contracted | N1: DataQualityFlag | O1: NetSpend_Clean | P1: Supplier_Category_Lookup | Q1: Savings_Target | R1: Potential_Saving
A2: =Procurement_Raw!A2 -> 45798 | B2: =Procurement_Raw!B2 -> S006 | C2: =Procurement_Raw!C2 -> Birmingham Care & Education Centre | D2: =Procurement_Raw!D2 -> Midlands | E2: =Procurement_Raw!E2 -> freshserve | F2: =Procurement_Raw!F2 -> Food & Catering | G2: =Procurement_Raw!G2 -> INV-2025-00001 | H2: =Procurement_Raw!H2 -> 32 | ... N2: =Procurement_Raw!N2 -> 2733.44 | O2: =IFERROR(IF(J2="","",J2),0) -> 2733.44 | P2: =IFERROR(INDEX(Supplier_Lookup!$B$2:$B$200,MATCH(E2,Supplier_Lookup!$A$2:$A$200,0)),"Unmapped") -> Food & Catering | Q2: =IFERROR(INDEX(Category_Targets!$B$2:$B$9,MATCH(F2,Category_Targets!$A$2:$A$9,0)),0) -> 0.04 | R2: =O2*Q2 -> 109.3376
A3: =Procurement_Raw!A3 -> 45937 | B3: =Procurement_Raw!B3 -> S008 | C3: =Procurement_Raw!C3 -> Leicester Care & Education Centre | D3: =Procurement_Raw!D3 -> Midlands | E3: =Procurement_Raw!E3 -> KitchenPro | F3: =Procurement_Raw!F3 -> Food & Catering | G3: =Procurement_Raw!G3 -> INV-2025-00002 | H3: =Procurement_Raw!H3 -> 12 | ... N3: =Procurement_Raw!N3 -> 722.88 | O3: =IFERROR(IF(J3="","",J3),0) -> 722.88 | P3: =IFERROR(INDEX(Supplier_Lookup!$B$2:$B$200,MATCH(E3,Supplier_Lookup!$A$2:$A$200,0)),"Unmapped") -> Food & Catering | Q3: =IFERROR(INDEX(Category_Targets!$B$2:$B$9,MATCH(F3,Category_Targets!$A$2:$A$9,0)),0) -> 0.04 | R3: =O3*Q3 -> 28.9152
A4: =Procurement_Raw!A4 -> 45769 | B4: =Procurement_Raw!B4 -> S009 | C4: =Procurement_Raw!C4 -> Derby Care & Education Centre | D4: =Procurement_Raw!D4 -> Midlands | E4: =Procurement_Raw!E4 -> MediSure | F4: =Procurement_Raw!F4 -> Medical Supplies | G4: =Procurement_Raw!G4 -> INV-2025-00003 | H4: =Procurement_Raw!H4 -> 30 | ... N4: =Procurement_Raw!N4 -> 5140.56 | O4: =IFERROR(IF(J4="","",J4),0) -> 5140.56 | P4: =IFERROR(INDEX(Supplier_Lookup!$B$2:$B$200,MATCH(E4,Supplier_Lookup!$A$2:$A$200,0)),"Unmapped") -> Medical Supplies | Q4: =IFERROR(INDEX(Category_Targets!$B$2:$B$9,MATCH(F4,Category_Targets!$A$2:$A$9,0)),0) -> 0.06 | R4: =O4*Q4 -> 308.4336
A5: =Procurement_Raw!A5 -> 45990 | B5: =Procurement_Raw!B5 -> S006 | C5: =Procurement_Raw!C5 -> Birmingham Care & Education Centre | D5: =Procurement_Raw!D5 -> Midlands | E5: =Procurement_Raw!E5 -> PowerDirect | F5: =Procurement_Raw!F5 -> Utilities | G5: =Procurement_Raw!G5 -> INV-2025-00004 | H5: =Procurement_Raw!H5 -> 70 | ... N5: =Procurement_Raw!N5 -> 40441.94 | O5: =IFERROR(IF(J5="","",J5),0) -> 40441.94 | P5: =IFERROR(INDEX(Supplier_Lookup!$B$2:$B$200,MATCH(E5,Supplier_Lookup!$A$2:$A$200,0)),"Unmapped") -> Utilities | Q5: =IFERROR(INDEX(Category_Targets!$B$2:$B$9,MATCH(F5,Category_Targets!$A$2:$A$9,0)),0) -> 0.03 | R5: =O5*Q5 -> 1213.2582
A6: =Procurement_Raw!A6 -> 45739 | B6: =Procurement_Raw!B6 -> S016 | C6: =Procurement_Raw!C6 -> Cardiff Care & Education Centre | D6: =Procurement_Raw!D6 -> Wales | E6: =Procurement_Raw!E6 -> CloudLink | F6: =Procurement_Raw!F6 -> IT & Telecoms | G6: =Procurement_Raw!G6 -> INV-2025-00005 | H6: =Procurement_Raw!H6 -> 55 | ... N6: =Procurement_Raw!N6 -> 10637.88 | O6: =IFERROR(IF(J6="","",J6),0) -> 10637.88 | P6: =IFERROR(INDEX(Supplier_Lookup!$B$2:$B$200,MATCH(E6,Supplier_Lookup!$A$2:$A$200,0)),"Unmapped") -> medical supplies | Q6: =IFERROR(INDEX(Category_Targets!$B$2:$B$9,MATCH(F6,Category_Targets!$A$2:$A$9,0)),0) -> 0.08 | R6: =O6*Q6 -> 851.0304
A7: =Procurement_Raw!A7 -> 45710 | B7: =Procurement_Raw!B7 -> S013 | C7: =Procurement_Raw!C7 -> Reading Care & Education Centre | D7: =Procurement_Raw!D7 -> South | E7: =Procurement_Raw!E7 -> WaterGrid | F7: =Procurement_Raw!F7 -> Utilities | G7: =Procurement_Raw!G7 -> INV-2025-00006 | H7: =Procurement_Raw!H7 -> 12 | ... N7: =Procurement_Raw!N7 -> 2637.51 | O7: =IFERROR(IF(J7="","",J7),0) -> 2637.51 | P7: =IFERROR(INDEX(Supplier_Lookup!$B$2:$B$200,MATCH(E7,Supplier_Lookup!$A$2:$A$200,0)),"Unmapped") -> Utilities | Q7: =IFERROR(INDEX(Category_Targets!$B$2:$B$9,MATCH(F7,Category_Targets!$A$2:$A$9,0)),0) -> 0.03 | R7: =O7*Q7 -> 79.1253
A8: =Procurement_Raw!A8 -> 45793 | B8: =Procurement_Raw!B8 -> S005 | C8: =Procurement_Raw!C8 -> Sheffield Care & Education Centre | D8: =Procurement_Raw!D8 -> North | E8: =Procurement_Raw!E8 -> AutoCare | F8: =Procurement_Raw!F8 -> Vehicle & Fuel | G8: =Procurement_Raw!G8 -> INV-2025-00007 | H8: =Procurement_Raw!H8 -> 6 | ... N8: =Procurement_Raw!N8 -> 1358.59 | O8: =IFERROR(IF(J8="","",J8),0) -> 1358.59 | P8: =IFERROR(INDEX(Supplier_Lookup!$B$2:$B$200,MATCH(E8,Supplier_Lookup!$A$2:$A$200,0)),"Unmapped") -> Vehicle & Fuel | Q8: =IFERROR(INDEX(Category_Targets!$B$2:$B$9,MATCH(F8,Category_Targets!$A$2:$A$9,0)),0) -> 0.05 | R8: =O8*Q8 -> 67.9295
A9: =Procurement_Raw!A9 -> 45698 | B9: =Procurement_Raw!B9 -> S004 | C9: =Procurement_Raw!C9 -> Newcastle Care & Education Centre | D9: =Procurement_Raw!D9 -> North | E9: =Procurement_Raw!E9 -> NourishCo | F9: =Procurement_Raw!F9 -> Food & Catering | G9: =Procurement_Raw!G9 -> INV-2025-00008 | H9: =Procurement_Raw!H9 -> 71 | ... N9: =Procurement_Raw!N9 -> 7038.54 | O9: =IFERROR(IF(J9="","",J9),0) -> 7038.54 | P9: =IFERROR(INDEX(Supplier_Lookup!$B$2:$B$200,MATCH(E9,Supplier_Lookup!$A$2:$A$200,0)),"Unmapped") -> Food & Catering | Q9: =IFERROR(INDEX(Category_Targets!$B$2:$B$9,MATCH(F9,Category_Targets!$A$2:$A$9,0)),0) -> 0.04 | R9: =O9*Q9 -> 281.5416
A10: =Procurement_Raw!A10 -> 45756 | B10: =Procurement_Raw!B10 -> S017 | C10: =Procurement_Raw!C10 -> Swansea Care & Education Centre | D10: =Procurement_Raw!D10 -> Wales | E10: =Procurement_Raw!E10 -> AutoCare | F10: =Procurement_Raw!F10 -> Vehicle & Fuel | G10: =Procurement_Raw!G10 -> INV-2025-00009 | H10: =Procurement_Raw!H10 -> 9 | ... N10: =Procurement_Raw!N10 -> 660.43 | O10: =IFERROR(IF(J10="","",J10),0) -> 660.43 | P10: =IFERROR(INDEX(Supplier_Lookup!$B$2:$B$200,MATCH(E10,Supplier_Lookup!$A$2:$A$200,0)),"Unmapped") -> Vehicle & Fuel | Q10: =IFERROR(INDEX(Category_Targets!$B$2:$B$9,MATCH(F10,Category_Targets!$A$2:$A$9,0)),0) -> 0.05 | R10: =O10*Q10 -> 33.0215
A11: =Procurement_Raw!A11 -> 45777 | B11: =Procurement_Raw!B11 -> S015 | C11: =Procurement_Raw!C11 -> Brighton Care & Education Centre | D11: =Procurement_Raw!D11 -> South | E11: =Procurement_Raw!E11 -> CloudLink | F11: =Procurement_Raw!F11 -> IT & Telecoms | G11: =Procurement_Raw!G11 -> INV-2025-00010 | H11: =Procurement_Raw!H11 -> 13 | ... N11: =Procurement_Raw!N11 -> 3854.46 | O11: =IFERROR(IF(J11="","",J11),0) -> 3854.46 | P11: =IFERROR(INDEX(Supplier_Lookup!$B$2:$B$200,MATCH(E11,Supplier_Lookup!$A$2:$A$200,0)),"Unmapped") -> medical supplies | Q11: =IFERROR(INDEX(Category_Targets!$B$2:$B$9,MATCH(F11,Category_Targets!$A$2:$A$9,0)),0) -> 0.08 | R11: =O11*Q11 -> 308.3568
A12: =Procurement_Raw!A12 -> 45847 | B12: =Procurement_Raw!B12 -> S016 | C12: =Procurement_Raw!C12 -> Cardiff Care & Education Centre | D12: =Procurement_Raw!D12 -> Wales | E12: =Procurement_Raw!E12 -> FleetFuel | F12: =Procurement_Raw!F12 -> Vehicle & Fuel | G12: =Procurement_Raw!G12 -> INV-2025-00011 | H12: =Procurement_Raw!H12 -> 46 | ... N12: =Procurement_Raw!N12 -> 3386.79 | O12: =IFERROR(IF(J12="","",J12),0) -> 3386.79 | P12: =IFERROR(INDEX(Supplier_Lookup!$B$2:$B$200,MATCH(E12,Supplier_Lookup!$A$2:$A$200,0)),"Unmapped") -> Vehicle & Fuel | Q12: =IFERROR(INDEX(Category_Targets!$B$2:$B$9,MATCH(F12,Category_Targets!$A$2:$A$9,0)),0) -> 0.05 | R12: =O12*Q12 -> 169.3395
A13: =Procurement_Raw!A13 -> 45983 | B13: =Procurement_Raw!B13 -> S019 | C13: =Procurement_Raw!C13 -> Wrexham Care & Education Centre | D13: =Procurement_Raw!D13 -> Wales | E13: =Procurement_Raw!E13 -> KitchenPro | F13: =Procurement_Raw!F13 -> Food & Catering | G13: =Procurement_Raw!G13 -> INV-2025-00012 | H13: =Procurement_Raw!H13 -> 22 | ... N13: =Procurement_Raw!N13 -> 1106.86 | O13: =IFERROR(IF(J13="","",J13),0) -> 1106.86 | P13: =IFERROR(INDEX(Supplier_Lookup!$B$2:$B$200,MATCH(E13,Supplier_Lookup!$A$2:$A$200,0)),"Unmapped") -> Food & Catering | Q13: =IFERROR(INDEX(Category_Targets!$B$2:$B$9,MATCH(F13,Category_Targets!$A$2:$A$9,0)),0) -> 0.04 | R13: =O13*Q13 -> 44.2744
... A1801: =Procurement_Raw!A1801 -> 45981 | B1801: =Procurement_Raw!B1801 -> S020 | C1801: =Procurement_Raw!C1801 -> Bangor Care & Education Centre | D1801: =Procurement_Raw!D1801 -> Wales | E1801: =Procurement_Raw!E1801 -> PrintCo | F1801: =Procurement_Raw!F1801 -> Office & Training | G1801: =Procurement_Raw!G1801 -> INV-2025-01800 | H1801: =Procurement_Raw!H1801 -> 46 | ... N1801: =Procurement_Raw!N1801 -> 3490.68 | O1801: =IFERROR(IF(J1801="","",J1801),0) -> 3490.68 | P1801: =IFERROR(INDEX(Supplier_Lookup!$B$2:$B$200,MATCH(E1801,Supplier_Lookup!$A$2:$A$200,0)),"Unmapped") -> Office & Training | Q1801: =IFERROR(INDEX(Category_Targets!$B$2:$B$9,MATCH(F1801,Category_Targets!$A$2:$A$9,0)),0) -> 0.04 | R1801: =O1801*Q1801 -> 139.6272

Sheet Pivot_Analysis
A1: Pivot-Style Commercial Analysis – Refreshable Formula Summary
A3: Spend by Category
A4: Category | B4: Spend | C4: % of Total | D4: Target Savings | E4: Potential Saving | F4: Contracted Spend | G4: Non-Contracted Spend
A5: Medical Supplies | B5: =SUMIFS(Cleaned_Procurement!$O:$O,Cleaned_Procurement!$F:$F,A5) -> 1097153 | C5: =IFERROR(B5/SUM($B$5:$B$12),0) -> 0.078803282 | D5: =IFERROR(INDEX(Category_Targets!$B$2:$B$9,MATCH(A5,Category_Targets!$A$2:$A$9,0)),0) -> 0.06 | E5: =B5*D5 -> 65829.181 | F5: =SUMIFS(Cleaned_Procurement!$O:$O,Cleaned_Procurement!$F:$F,A5,Cleaned_Procurement!$M:$M,"Y") -> 0 | G5: =B5-F5 -> 1097153
A6: Food & Catering | B6: =SUMIFS(Cleaned_Procurement!$O:$O,Cleaned_Procurement!$F:$F,A6) -> 837713.63 | C6: =IFERROR(B6/SUM($B$5:$B$12),0) -> 0.060168985 | D6: =IFERROR(INDEX(Category_Targets!$B$2:$B$9,MATCH(A6,Category_Targets!$A$2:$A$9,0)),0) -> 0.04 | E6: =B6*D6 -> 33508.545 | F6: =SUMIFS(Cleaned_Procurement!$O:$O,Cleaned_Procurement!$F:$F,A6,Cleaned_Procurement!$M:$M,"Y") -> 0 | G6: =B6-F6 -> 837713.63
A7: Facilities | B7: =SUMIFS(Cleaned_Procurement!$O:$O,Cleaned_Procurement!$F:$F,A7) -> 2128780.9 | C7: =IFERROR(B7/SUM($B$5:$B$12),0) -> 0.15290021 | D7: =IFERROR(INDEX(Category_Targets!$B$2:$B$9,MATCH(A7,Category_Targets!$A$2:$A$9,0)),0) -> 0.05 | E7: =B7*D7 -> 106439.05 | F7: =SUMIFS(Cleaned_Procurement!$O:$O,Cleaned_Procurement!$F:$F,A7,Cleaned_Procurement!$M:$M,"Y") -> 0 | G7: =B7-F7 -> 2128780.9
A8: Utilities | B8: =SUMIFS(Cleaned_Procurement!$O:$O,Cleaned_Procurement!$F:$F,A8) -> 2401261.6 | C8: =IFERROR(B8/SUM($B$5:$B$12),0) -> 0.1724712 | D8: =IFERROR(INDEX(Category_Targets!$B$2:$B$9,MATCH(A8,Category_Targets!$A$2:$A$9,0)),0) -> 0.03 | E8: =B8*D8 -> 72037.848 | F8: =SUMIFS(Cleaned_Procurement!$O:$O,Cleaned_Procurement!$F:$F,A8,Cleaned_Procurement!$M:$M,"Y") -> 0 | G8: =B8-F8 -> 2401261.6
A9: IT & Telecoms | B9: =SUMIFS(Cleaned_Procurement!$O:$O,Cleaned_Procurement!$F:$F,A9) -> 2505155.2 | C9: =IFERROR(B9/SUM($B$5:$B$12),0) -> 0.17993338 | D9: =IFERROR(INDEX(Category_Targets!$B$2:$B$9,MATCH(A9,Category_Targets!$A$2:$A$9,0)),0) -> 0.08 | E9: =B9*D9 -> 200412.41 | F9: =SUMIFS(Cleaned_Procurement!$O:$O,Cleaned_Procurement!$F:$F,A9,Cleaned_Procurement!$M:$M,"Y") -> 0 | G9: =B9-F9 -> 2505155.2
A10: Vehicle & Fuel | B10: =SUMIFS(Cleaned_Procurement!$O:$O,Cleaned_Procurement!$F:$F,A10) -> 1030620.3 | C10: =IFERROR(B10/SUM($B$5:$B$12),0) -> 0.074024553 | D10: =IFERROR(INDEX(Category_Targets!$B$2:$B$9,MATCH(A10,Category_Targets!$A$2:$A$9,0)),0) -> 0.05 | E10: =B10*D10 -> 51531.015 | F10: =SUMIFS(Cleaned_Procurement!$O:$O,Cleaned_Procurement!$F:$F,A10,Cleaned_Procurement!$M:$M,"Y") -> 0 | G10: =B10-F10 -> 1030620.3
A11: Agency Labour | B11: =SUMIFS(Cleaned_Procurement!$O:$O,Cleaned_Procurement!$F:$F,A11) -> 3193367.1 | C11: =IFERROR(B11/SUM($B$5:$B$12),0) -> 0.22936437 | D11: =IFERROR(INDEX(Category_Targets!$B$2:$B$9,MATCH(A11,Category_Targets!$A$2:$A$9,0)),0) -> 0.07 | E11: =B11*D11 -> 223535.7 | F11: =SUMIFS(Cleaned_Procurement!$O:$O,Cleaned_Procurement!$F:$F,A11,Cleaned_Procurement!$M:$M,"Y") -> 0 | G11: =B11-F11 -> 3193367.1
A12: Office & Training | B12: =SUMIFS(Cleaned_Procurement!$O:$O,Cleaned_Procurement!$F:$F,A12) -> 728629.96 | C12: =IFERROR(B12/SUM($B$5:$B$12),0) -> 0.052334024 | D12: =IFERROR(INDEX(Category_Targets!$B$2:$B$9,MATCH(A12,Category_Targets!$A$2:$A$9,0)),0) -> 0.04 | E12: =B12*D12 -> 29145.198 | F12: =SUMIFS(Cleaned_Procurement!$O:$O,Cleaned_Procurement!$F:$F,A12,Cleaned_Procurement!$M:$M,"Y") -> 0 | G12: =B12-F12 -> 728629.96
A15: Spend by Region
A16: Region | B16: Spend | C16: Invoices | D16: Avg Invoice | E16: Potential Saving
A17: North | B17: =SUMIFS(Cleaned_Procurement!$O:$O,Cleaned_Procurement!$D:$D,A17) -> 3330923.9 | C17: =COUNTIFS(Cleaned_Procurement!$D:$D,A17) -> 430 | D17: =IFERROR(B17/C17,0) -> 7746.3346 | E17: =SUMIFS(Cleaned_Procurement!$R:$R,Cleaned_Procurement!$D:$D,A17) -> 187081.69
A18: Midlands | B18: =SUMIFS(Cleaned_Procurement!$O:$O,Cleaned_Procurement!$D:$D,A18) -> 3517504.9 | C18: =COUNTIFS(Cleaned_Procurement!$D:$D,A18) -> 475 | D18: =IFERROR(B18/C18,0) -> 7405.2735 | E18: =SUMIFS(Cleaned_Procurement!$R:$R,Cleaned_Procurement!$D:$D,A18) -> 197841.61
A19: South | B19: =SUMIFS(Cleaned_Procurement!$O:$O,Cleaned_Procurement!$D:$D,A19) -> 3350069.5 | C19: =COUNTIFS(Cleaned_Procurement!$D:$D,A19) -> 429 | D19: =IFERROR(B19/C19,0) -> 7809.0198 | E19: =SUMIFS(Cleaned_Procurement!$R:$R,Cleaned_Procurement!$D:$D,A19) -> 188355.79
A20: Wales | B20: =SUMIFS(Cleaned_Procurement!$O:$O,Cleaned_Procurement!$D:$D,A20) -> 3724183.5 | C20: =COUNTIFS(Cleaned_Procurement!$D:$D,A20) -> 466 | D20: =IFERROR(B20/C20,0) -> 7991.81 | E20: =SUMIFS(Cleaned_Procurement!$R:$R,Cleaned_Procurement!$D:$D,A20) -> 209159.87
A23: Monthly Finance Performance
A24: Month | B24: Revenue | C24: Actual Opex | D24: Budget Opex | E24: Variance | F24: EBITDA | G24: Margin
A25: 45658 | B25: =SUMIFS(Finance_Raw!$E:$E,Finance_Raw!$A:$A,A25) -> 6859245.2 | C25: =SUMIFS(Finance_Raw!$L:$L,Finance_Raw!$A:$A,A25) -> 4833404.3 | D25: =SUMIFS(Finance_Raw!$K:$K,Finance_Raw!$A:$A,A25) -> 4836088.8 | E25: =D25-C25 -> 2684.4533 | F25: =B25-C25 -> 2025840.9 | G25: =IFERROR(F25/B25,0) -> 0.29534458
A26: 45689 | B26: =SUMIFS(Finance_Raw!$E:$E,Finance_Raw!$A:$A,A26) -> 7476589.8 | C26: =SUMIFS(Finance_Raw!$L:$L,Finance_Raw!$A:$A,A26) -> 5235379.8 | D26: =SUMIFS(Finance_Raw!$K:$K,Finance_Raw!$A:$A,A26) -> 5267039.7 | E26: =D26-C26 -> 31659.923 | F26: =B26-C26 -> 2241210 | G26: =IFERROR(F26/B26,0) -> 0.29976367
A27: 45717 | B27: =SUMIFS(Finance_Raw!$E:$E,Finance_Raw!$A:$A,A27) -> 7345583.3 | C27: =SUMIFS(Finance_Raw!$L:$L,Finance_Raw!$A:$A,A27) -> 5087641.7 | D27: =SUMIFS(Finance_Raw!$K:$K,Finance_Raw!$A:$A,A27) -> 5095798.3 | E27: =D27-C27 -> 8156.6533 | F27: =B27-C27 -> 2257941.6 | G27: =IFERROR(F27/B27,0) -> 0.30738766
A28: 45748 | B28: =SUMIFS(Finance_Raw!$E:$E,Finance_Raw!$A:$A,A28) -> 7658852.2 | C28: =SUMIFS(Finance_Raw!$L:$L,Finance_Raw!$A:$A,A28) -> 5279230.4 | D28: =SUMIFS(Finance_Raw!$K:$K,Finance_Raw!$A:$A,A28) -> 5236666.6 | E28: =D28-C28 -> -42563.747 | F28: =B28-C28 -> 2379621.9 | G28: =IFERROR(F28/B28,0) -> 0.31070215
A29: 45778 | B29: =SUMIFS(Finance_Raw!$E:$E,Finance_Raw!$A:$A,A29) -> 6576496.4 | C29: =SUMIFS(Finance_Raw!$L:$L,Finance_Raw!$A:$A,A29) -> 4543655.4 | D29: =SUMIFS(Finance_Raw!$K:$K,Finance_Raw!$A:$A,A29) -> 4562622.3 | E29: =D29-C29 -> 18966.897 | F29: =B29-C29 -> 2032841 | G29: =IFERROR(F29/B29,0) -> 0.30910699
A30: 45809 | B30: =SUMIFS(Finance_Raw!$E:$E,Finance_Raw!$A:$A,A30) -> 7065637.8 | C30: =SUMIFS(Finance_Raw!$L:$L,Finance_Raw!$A:$A,A30) -> 4919918.3 | D30: =SUMIFS(Finance_Raw!$K:$K,Finance_Raw!$A:$A,A30) -> 4907337.8 | E30: =D30-C30 -> -12580.503 | F30: =B30-C30 -> 2145719.5 | G30: =IFERROR(F30/B30,0) -> 0.30368377
A31: 45839 | B31: =SUMIFS(Finance_Raw!$E:$E,Finance_Raw!$A:$A,A31) -> 6953277 | C31: =SUMIFS(Finance_Raw!$L:$L,Finance_Raw!$A:$A,A31) -> 4875601.1 | D31: =SUMIFS(Finance_Raw!$K:$K,Finance_Raw!$A:$A,A31) -> 4898226.2 | E31: =D31-C31 -> 22625.13 | F31: =B31-C31 -> 2077675.9 | G31: =IFERROR(F31/B31,0) -> 0.29880529
A32: 45870 | B32: =SUMIFS(Finance_Raw!$E:$E,Finance_Raw!$A:$A,A32) -> 7044378.2 | C32: =SUMIFS(Finance_Raw!$L:$L,Finance_Raw!$A:$A,A32) -> 4979875.7 | D32: =SUMIFS(Finance_Raw!$K:$K,Finance_Raw!$A:$A,A32) -> 4993843.2 | E32: =D32-C32 -> 13967.497 | F32: =B32-C32 -> 2064502.5 | G32: =IFERROR(F32/B32,0) -> 0.29307093
A33: 45901 | B33: =SUMIFS(Finance_Raw!$E:$E,Finance_Raw!$A:$A,A33) -> 6899634.7 | C33: =SUMIFS(Finance_Raw!$L:$L,Finance_Raw!$A:$A,A33) -> 4818773.5 | D33: =SUMIFS(Finance_Raw!$K:$K,Finance_Raw!$A:$A,A33) -> 4850993.2 | E33: =D33-C33 -> 32219.643 | F33: =B33-C33 -> 2080861.1 | G33: =IFERROR(F33/B33,0) -> 0.30159004
A34: 45931 | B34: =SUMIFS(Finance_Raw!$E:$E,Finance_Raw!$A:$A,A34) -> 8051254.3 | C34: =SUMIFS(Finance_Raw!$L:$L,Finance_Raw!$A:$A,A34) -> 5558744.3 | D34: =SUMIFS(Finance_Raw!$K:$K,Finance_Raw!$A:$A,A34) -> 5591688.3 | E34: =D34-C34 -> 32944.003 | F34: =B34-C34 -> 2492510 | G34: =IFERROR(F34/B34,0) -> 0.30958034
A35: 45962 | B35: =SUMIFS(Finance_Raw!$E:$E,Finance_Raw!$A:$A,A35) -> 6479152 | C35: =SUMIFS(Finance_Raw!$L:$L,Finance_Raw!$A:$A,A35) -> 4606613.7 | D35: =SUMIFS(Finance_Raw!$K:$K,Finance_Raw!$A:$A,A35) -> 4585980.7 | E35: =D35-C35 -> -20633.017 | F35: =B35-C35 -> 1872538.3 | G35: =IFERROR(F35/B35,0) -> 0.28900979
A36: 45992 | B36: =SUMIFS(Finance_Raw!$E:$E,Finance_Raw!$A:$A,A36) -> 8066416.4 | C36: =SUMIFS(Finance_Raw!$L:$L,Finance_Raw!$A:$A,A36) -> 5614126.6 | D36: =SUMIFS(Finance_Raw!$K:$K,Finance_Raw!$A:$A,A36) -> 5575536.7 | E36: =D36-C36 -> -38589.957 | F36: =B36-C36 -> 2452289.7 | G36: =IFERROR(F36/B36,0) -> 0.30401229

Sheet Financial_Model
A1: 2026 Driver-Based Commercial Financial Model
A3: Scenario | B3: Base
A5: Driver | B5: Conservative | C5: Base | D5: Aggressive | E5: Selected
A6: Revenue growth | B6: 0.01 | C6: 0.03 | D6: 0.05 | E6: =CHOOSE(MATCH($B$3,$B$5:$D$5,0),B6,C6,D6) -> 0.03
A7: Procurement savings | B7: 0.02 | C7: 0.04 | D7: 0.07 | E7: =CHOOSE(MATCH($B$3,$B$5:$D$5,0),B7,C7,D7) -> 0.04
A8: Agency rate inflation | B8: 0.06 | C8: 0.05 | D8: 0.03 | E8: =CHOOSE(MATCH($B$3,$B$5:$D$5,0),B8,C8,D8) -> 0.05
A9: Fleet efficiency | B9: 0.01 | C9: 0.03 | D9: 0.05 | E9: =CHOOSE(MATCH($B$3,$B$5:$D$5,0),B9,C9,D9) -> 0.03
A10: Payroll inflation | B10: 0.035 | C10: 0.025 | D10: 0.02 | E10: =CHOOSE(MATCH($B$3,$B$5:$D$5,0),B10,C10,D10) -> 0.025
A11: Other Opex inflation | B11: 0.04 | C11: 0.03 | D11: 0.02 | E11: =CHOOSE(MATCH($B$3,$B$5:$D$5,0),B11,C11,D11) -> 0.03
A14: 2025 Baseline
A15: Metric | B15: 2025 Actual | C15: 2026 Selected Scenario | D15: Change | E15: % Change
A16: Revenue | B16: =SUM(Finance_Raw!$E:$E) -> 86476517 | C16: =B16*(1+$E$6) -> 89070813 | D16: =C16-B16 -> 2594295.5 | E16: =IFERROR(D16/B16,0) -> 0.03
A17: Procurement | B17: =SUM(Finance_Raw!$G:$G) -> 13917019 | C17: =B17*(1-$E$7) -> 13360339 | D17: =C17-B17 -> -556680.77 | E17: =IFERROR(D17/B17,0) -> -0.04
A18: Agency | B18: =SUM(Finance_Raw!$I:$I) -> 1341086 | C18: =B18*(1+$E$8) -> 1408140.3 | D18: =C18-B18 -> 67054.3 | E18: =IFERROR(D18/B18,0) -> 0.05
A19: Fleet | B19: =SUM(Finance_Raw!$H:$H) -> 882007.36 | C19: =B19*(1-$E$9) -> 855547.14 | D19: =C19-B19 -> -26460.221 | E19: =IFERROR(D19/B19,0) -> -0.03
A20: Payroll | B20: =SUM(Finance_Raw!$F:$F) -> 38123646 | C20: =B20*(1+$E$10) -> 39076737 | D20: =C20-B20 -> 953091.15 | E20: =IFERROR(D20/B20,0) -> 0.025
A21: Other Opex | B21: =SUM(Finance_Raw!$J:$J) -> 6089205.9 | C21: =B21*(1+$E$11) -> 6271882.1 | D21: =C21-B21 -> 182676.18 | E21: =IFERROR(D21/B21,0) -> 0.03
A23: 2026 Forecast Profitability
A24: Metric | B24: Value
A25: Revenue | B25: =C16 -> 89070813
A26: Total Opex | B26: =SUM(C17:C21) -> 60972645
A27: EBITDA | B27: =B25-B26 -> 28098167
A28: EBITDA Margin | B28: =IFERROR(B27/B25,0) -> 0.31545875
A31: Scenario insight
A32: Use the scenario selector to test how procurement savings, agency inflation, fleet efficiency and payroll inflation affect 2026 EBITDA. This demonstrates driver-based modelling rather than a static budget.

Sheet Savings_Tracker
A1: Commercial Savings Tracker
A3: Category | B3: 2025 Spend | C3: Target % | D3: Target Saving | E3: 2026 Realised Saving | F3: Status
A4: Medical Supplies | B4: =SUMIFS(Cleaned_Procurement!$O:$O,Cleaned_Procurement!$F:$F,A4) -> 1097153 | C4: =IFERROR(INDEX(Category_Targets!$B$2:$B$9,MATCH(A4,Category_Targets!$A$2:$A$9,0)),0) -> 0.06 | D4: =B4*C4 -> 65829.181 | E4: =D4*85% -> 55954.804 | F4: =IF(E4>=D4,"On Target",IF(E4>=D4*0.75,"Watch","Off Track")) -> Watch
A5: Food & Catering | B5: =SUMIFS(Cleaned_Procurement!$O:$O,Cleaned_Procurement!$F:$F,A5) -> 837713.63 | C5: =IFERROR(INDEX(Category_Targets!$B$2:$B$9,MATCH(A5,Category_Targets!$A$2:$A$9,0)),0) -> 0.04 | D5: =B5*C5 -> 33508.545 | E5: =D5*85% -> 28482.263 | F5: =IF(E5>=D5,"On Target",IF(E5>=D5*0.75,"Watch","Off Track")) -> Watch
A6: Facilities | B6: =SUMIFS(Cleaned_Procurement!$O:$O,Cleaned_Procurement!$F:$F,A6) -> 2128780.9 | C6: =IFERROR(INDEX(Category_Targets!$B$2:$B$9,MATCH(A6,Category_Targets!$A$2:$A$9,0)),0) -> 0.05 | D6: =B6*C6 -> 106439.05 | E6: =D6*85% -> 90473.19 | F6: =IF(E6>=D6,"On Target",IF(E6>=D6*0.75,"Watch","Off Track")) -> Watch
A7: Utilities | B7: =SUMIFS(Cleaned_Procurement!$O:$O,Cleaned_Procurement!$F:$F,A7) -> 2401261.6 | C7: =IFERROR(INDEX(Category_Targets!$B$2:$B$9,MATCH(A7,Category_Targets!$A$2:$A$9,0)),0) -> 0.03 | D7: =B7*C7 -> 72037.848 | E7: =D7*85% -> 61232.171 | F7: =IF(E7>=D7,"On Target",IF(E7>=D7*0.75,"Watch","Off Track")) -> Watch
A8: IT & Telecoms | B8: =SUMIFS(Cleaned_Procurement!$O:$O,Cleaned_Procurement!$F:$F,A8) -> 2505155.2 | C8: =IFERROR(INDEX(Category_Targets!$B$2:$B$9,MATCH(A8,Category_Targets!$A$2:$A$9,0)),0) -> 0.08 | D8: =B8*C8 -> 200412.41 | E8: =D8*85% -> 170350.55 | F8: =IF(E8>=D8,"On Target",IF(E8>=D8*0.75,"Watch","Off Track")) -> Watch
A9: Vehicle & Fuel | B9: =SUMIFS(Cleaned_Procurement!$O:$O,Cleaned_Procurement!$F:$F,A9) -> 1030620.3 | C9: =IFERROR(INDEX(Category_Targets!$B$2:$B$9,MATCH(A9,Category_Targets!$A$2:$A$9,0)),0) -> 0.05 | D9: =B9*C9 -> 51531.015 | E9: =D9*85% -> 43801.363 | F9: =IF(E9>=D9,"On Target",IF(E9>=D9*0.75,"Watch","Off Track")) -> Watch
A10: Agency Labour | B10: =SUMIFS(Cleaned_Procurement!$O:$O,Cleaned_Procurement!$F:$F,A10) -> 3193367.1 | C10: =IFERROR(INDEX(Category_Targets!$B$2:$B$9,MATCH(A10,Category_Targets!$A$2:$A$9,0)),0) -> 0.07 | D10: =B10*C10 -> 223535.7 | E10: =D10*85% -> 190005.34 | F10: =IF(E10>=D10,"On Target",IF(E10>=D10*0.75,"Watch","Off Track")) -> Watch
A11: Office & Training | B11: =SUMIFS(Cleaned_Procurement!$O:$O,Cleaned_Procurement!$F:$F,A11) -> 728629.96 | C11: =IFERROR(INDEX(Category_Targets!$B$2:$B$9,MATCH(A11,Category_Targets!$A$2:$A$9,0)),0) -> 0.04 | D11: =B11*C11 -> 29145.198 | E11: =D11*85% -> 24773.419 | F11: =IF(E11>=D11,"On Target",IF(E11>=D11*0.75,"Watch","Off Track")) -> Watch
A13: Total | B13: =SUM(B4:B11) -> 13922682 | C13: =SUM(C4:C11) -> 0.42 | D13: =SUM(D4:D11) -> 782438.95 | E13: =SUM(E4:E11) -> 665073.11

Sheet Formula_Audit
A1: Advanced Formula Catalogue
A3: Technique | B3: Example formula / use
A4: SUMIFS | B4: Aggregate spend by category, region and contracted status.
A5: COUNTIFS | B5: Count invoices by region/category.
A6: IFERROR | B6: Handle missing lookup keys and blank spend safely.
A7: INDEX + MATCH | B7: Return category savings target from lookup table.
A8: VLOOKUP / XLOOKUP | B8: Demonstrated in the VBA/technical notes for supplier and site enrichment; INDEX/MATCH is used in the live model for broad compatibility.
A9: CHOOSE + MATCH | B9: Scenario selector maps Conservative/Base/Aggressive assumptions to selected driver values.
A10: Structured tables | B10: All raw source datasets are Excel Tables for filterable, extensible ranges.
A11: Conditional formatting | B11: Flags data-quality issues, savings status and model driver changes.
A12: Data validation | B12: Scenario selector restricts inputs to approved scenario names.
A13: Pivot-style summaries | B13: Formula-driven cross-tabs replicate common PivotTable questions and remain refreshable when source rows change.
A14: Financial modelling | B14: Driver-based forecast, savings tracker, EBITDA and margin analysis.

Sheet Dashboard
B2: CARETECH COMMERCIAL ANALYTICS – EXECUTIVE EXCEL DASHBOARD
B5: 2025 Total Revenue | E5: 2025 Actual Opex | H5: 2025 EBITDA | K5: Potential Savings
B6: =SUM(Finance_Raw!$E:$E) -> 86476517 | E6: =SUM(Finance_Raw!$L:$L) -> 60352965 | H6: =B6-E6 -> 26123553 | K6: =SUM(Pivot_Analysis!$E$5:$E$12) -> 782438.95
B9: Commercial insights
B10: Largest spend category | C10: =INDEX(Pivot_Analysis!$A$5:$A$12,MATCH(MAX(Pivot_Analysis!$B$5:$B$12),Pivot_Analysis!$B$5:$B$12,0)) -> Agency Labour
B11: Highest savings opportunity | C11: =INDEX(Pivot_Analysis!$A$5:$A$12,MATCH(MAX(Pivot_Analysis!$E$5:$E$12),Pivot_Analysis!$E$5:$E$12,0)) -> Agency Labour
B12: 2025 EBITDA margin | C12: =IFERROR(H6/B6,0) -> 0.3020884

Sheet VBA_Code
A1: VBA Automation – Scripts Supplied Separately as .bas Files
A4: Module_CleanseData.bas | B4: Cleans text/case, identifies blank supplier/site/spend, and flags duplicate invoice IDs in a source table.
A5: Module_ConsolidateCSVs.bas | B5: Loops through a selected folder, opens CSV files, appends rows into a Consolidated sheet and closes source files.
A6: Module_RefreshDashboard.bas | B6: Refreshes workbook calculations, tables and PivotTables/queries where present, then records refresh timestamp.
A7: Module_ExportReport.bas | B7: Exports Dashboard to PDF for recurring commercial reporting.
A8: Use | B8: Open Excel desktop > Alt+F11 > File > Import File > select .bas. Save a copy as .xlsm before running macros. Test in a controlled folder first.

Sheet Methodology
A1: Data Dictionary & Methodology
A4: Data provenance | B4: Synthetic data generated specifically for this portfolio project. It is designed to resemble commercial care-sector datasets without using personal or confidential information.
A5: Procurement | B5: Invoice-level supplier spend with categories, contract status and deliberate quality exceptions.
A6: Fleet | B6: Monthly vehicle usage, fuel, maintenance and lease costs by site.
A7: Workforce | B7: Monthly FTE, salary, overtime and absence measures by role and site.
A8: Agency | B8: Monthly agency hours and rates by role and site.
A9: Finance | B9: Monthly revenue, cost components, budget, EBITDA and margin by site.
A10: GDPR-first design | B10: No names, addresses, phone numbers, NHS numbers or staff identifiers. Only synthetic IDs and aggregated operational measures are used.
A11: Quality checks | B11: Blank supplier/site/spend, duplicate invoice IDs and inconsistent category casing are deliberately included so the VBA module has a realistic cleansing use case.
A12: Financial model | B12: 2026 forecast uses 2025 actuals as the baseline. Scenario drivers alter revenue growth, procurement savings, agency inflation, fleet efficiency, payroll inflation and other Opex inflation.
A13: Limitations | B13: This is a portfolio simulation. It does not reproduce CareTech systems, contractual definitions or actual commercial policies. The candidate should explain this honestly in an interview.

Sheet Actual_Pivot
B3: Filter
D5: Region
B6: Category | C6: Data | D6: Midlands | E6: North | F6: South | G6: Wales | H6: Total Result
B7: Agency Labour | C7: Sum - NetSpend_Clean | D7: 908801.36 | E7: 909631.92 | F7: 573632.97 | G7: 801300.89 | H7: 3193367.1
C8: Count - InvoiceID | D8: 71 | E8: 61 | F8: 47 | G8: 63 | H8: 242
B9: Facilities | C9: Sum - NetSpend_Clean | D9: 507503.34 | E9: 527974.36 | F9: 535792.4 | G9: 557510.83 | H9: 2128780.9
C10: Count - InvoiceID | D10: 61 | E10: 59 | F10: 47 | G10: 50 | H10: 217
B11: Food & Catering | C11: Sum - NetSpend_Clean | D11: 235271.73 | E11: 229341.28 | F11: 184595.52 | G11: 188505.1 | H11: 837713.63
C12: Count - InvoiceID | D12: 64 | E12: 59 | F12: 62 | G12: 63 | H12: 248
B13: IT & Telecoms | C13: Sum - NetSpend_Clean | D13: 569180.44 | E13: 467580.07 | F13: 747410.31 | G13: 720984.36 | H13: 2505155.2
C14: Count - InvoiceID | D14: 56 | E14: 51 | F14: 66 | G14: 66 | H14: 239
B15: Medical Supplies | C15: Sum - NetSpend_Clean | D15: 235168.46 | E15: 271997.11 | F15: 280015.5 | G15: 309971.94 | H15: 1097153
C16: Count - InvoiceID | D16: 46 | E16: 49 | F16: 54 | G16: 56 | H16: 205
B17: Office & Training | C17: Sum - NetSpend_Clean | D17: 201318.8 | E17: 191459.22 | F17: 192086.25 | G17: 143765.69 | H17: 728629.96
C18: Count - InvoiceID | D18: 62 | E18: 52 | F18: 55 | G18: 53 | H18: 222
B19: Utilities | C19: Sum - NetSpend_Clean | D19: 563542.93 | E19: 509825.77 | F19: 603799.51 | G19: 724093.39 | H19: 2401261.6
C20: Count - InvoiceID | D20: 49 | E20: 49 | F20: 54 | G20: 54 | H20: 206
B21: Vehicle & Fuel | C21: Sum - NetSpend_Clean | D21: 296717.86 | E21: 223114.15 | F21: 232737.02 | G21: 278051.27 | H21: 1030620.3
C22: Count - InvoiceID | D22: 66 | E22: 50 | F22: 44 | G22: 61 | H22: 221
B23: Total Sum - NetSpend_Clean | D23: 3517504.9 | E23: 3330923.9 | F23: 3350069.5 | G23: 3724183.5 | H23: 13922682
B24: Total Count - InvoiceID | D24: 475 | E24: 430 | F24: 429 | G24: 466 | H24: 1800
